5:return {{["x"] = 2, ["meta"] = {["fields"] = {}, ["inventory"] = {}}, ["y"] = 6, ["param1"] = 13, ["z"] = 6, ["name"] = "appletree:leaves"}, {["x"] = 2, ["meta"] = {["fields"] = {}, ["inventory"] = {}}, ["y"] = 6, ["param1"] = 13, ["z"] = 7, ["name"] = "appletree:leaves"}, {["x"] = 2, ["meta"] = {["fields"] = {}, ["inventory"] = {}}, ["param2"] = 1, ["y"] = 7, ["param1"] = 13, ["z"] = 0, ["name"] = "appletree:leaves"}, {["x"] = 2, ["meta"] = {["fields"] = {}, ["inventory"] = {}}, ["param2"] = 1, ["y"] = 7, ["param1"] = 13, ["z"] = 3, ["name"] = "appletree:leaves"}, {["x"] = 2, ["meta"] = {["fields"] = {}, ["inventory"] = {}}, ["param2"] = 1, ["y"] = 7, ["param1"] = 13, ["z"] = 4, ["name"] = "appletree:leaves"}, {["x"] = 2, ["meta"] = {["fields"] = {}, ["inventory"] = {}}, ["y"] = 7, ["param1"] = 13, ["z"] = 5, ["name"] = "appletree:leaves"}, {["x"] = 2, ["meta"] = {["fields"] = {}, ["inventory"] = {}}, ["y"] = 7, ["param1"] = 13, ["z"] = 6, ["name"] = "appletree:leaves"}, {["x"] = 2, ["meta"] = {["fields"] = {}, ["inventory"] = {}}, ["y"] = 7, ["param1"] = 13, ["z"] = 7, ["name"] = "appletree:leaves"}, {["x"] = 2, ["meta"] = {["fields"] = {}, ["inventory"] = {}}, ["y"] = 8, ["param1"] = 13, ["z"] = 3, ["name"] = "appletree:leaves"}, {["x"] = 2, ["meta"] = {["fields"] = {}, ["inventory"] = {}}, ["param2"] = 1, ["y"] = 8, ["param1"] = 13, ["z"] = 4, ["name"] = "appletree:leaves"}, {["x"] = 2, ["meta"] = {["fields"] = {}, ["inventory"] = {}}, ["param2"] = 1, ["y"] = 8, ["param1"] = 13, ["z"] = 5, ["name"] = "appletree:leaves"}, {["x"] = 2, ["meta"] = {["fields"] = {}, ["inventory"] = {}}, ["y"] = 8, ["param1"] = 13, ["z"] = 7, ["name"] = "appletree:leaves"}, {["x"] = 2, ["meta"] = {["fields"] = {}, ["inventory"] = {}}, ["y"] = 9, ["param1"] = 13, ["z"] = 3, ["name"] = "appletree:leaves"}, {["x"] = 2, ["meta"] = {["fields"] = {}, ["inventory"] = {}}, ["y"] = 9, ["param1"] = 13, ["z"] = 4, ["name"] = "appletree:leaves"}, {["x"] = 2, ["meta"] = {["fields"] = {}, ["inventory"] = {}}, ["y"] = 9, ["param1"] = 13, ["z"] = 5, ["name"] = "appletree:leaves"}, {["x"] = 2, ["meta"] = {["fields"] = {}, ["inventory"] = {}}, ["param2"] = 1, ["y"] = 10, ["param1"] = 13, ["z"] = 5, ["name"] = "appletree:leaves"}, {["x"] = 3, ["meta"] = {["fields"] = {}, ["inventory"] = {}}, ["param2"] = 1, ["y"] = 0, ["param1"] = 12, ["z"] = 4, ["name"] = "doors:trapdoor_open"}, {["x"] = 3, ["meta"] = {["fields"] = {}, ["inventory"] = {}}, ["param2"] = 1, ["y"] = 0, ["param1"] = 12, ["z"] = 5, ["name"] = "doors:trapdoor_open"}, {["x"] = 3, ["meta"] = {["fields"] = {}, ["inventory"] = {}}, ["param2"] = 1, ["y"] = 0, ["param1"] = 12, ["z"] = 6, ["name"] = "doors:trapdoor_open"}, {["x"] = 3, ["meta"] = {["fields"] = {}, ["inventory"] = {}}, ["y"] = 6, ["param1"] = 13, ["z"] = 0, ["name"] = "appletree:leaves"}, {["x"] = 3, ["meta"] = {["fields"] = {}, ["inventory"] = {}}, ["param2"] = 1, ["y"] = 6, ["param1"] = 12, ["z"] = 3, ["name"] = "appletree:leaves"}, {["x"] = 3, ["meta"] = {["fields"] = {}, ["inventory"] = {}}, ["param2"] = 1, ["y"] = 6, ["param1"] = 12, ["z"] = 4, ["name"] = "appletree:leaves"}, {["x"] = 3, ["meta"] = {["fields"] = {}, ["inventory"] = {}}, ["y"] = 6, ["param1"] = 12, ["z"] = 5, ["name"] = "appletree:leaves"}, {["x"] = 3, ["meta"] = {["fields"] = {}, ["inventory"] = {}}, ["y"] = 6, ["param1"] = 12, ["z"] = 6, ["name"] = "appletree:leaves"}, {["x"] = 3, ["meta"] = {["fields"] = {}, ["inventory"] = {}}, ["y"] = 6, ["param1"] = 13, ["z"] = 7, ["name"] = "appletree:leaves"}, {["x"] = 3, ["meta"] = {["fields"] = {}, ["inventory"] = {}}, ["param2"] = 1, ["y"] = 7, ["param1"] = 13, ["z"] = 0, ["name"] = "appletree:leaves"}, {["x"] = 3, ["meta"] = {["fields"] = {}, ["inventory"] = {}}, ["y"] = 7, ["param1"] = 13, ["z"] = 2, ["name"] = "appletree:leaves"}, {["x"] = 3, ["meta"] = {["fields"] = {}, ["inventory"] = {}}, ["y"] = 7, ["param1"] = 12, ["z"] = 3, ["name"] = "appletree:leaves"}, {["x"] = 3, ["meta"] = {["fields"] = {}, ["inventory"] = {}}, ["param2"] = 1, ["y"] = 7, ["param1"] = 12, ["z"] = 4, ["name"] = "appletree:leaves"}, {["x"] = 3, ["meta"] = {["fields"] = {}, ["inventory"] = {}}, ["y"] = 7, ["param1"] = 12, ["z"] = 5, ["name"] = "appletree:leaves"}, {["x"] = 3, ["meta"] = {["fields"] = {}, ["inventory"] = {}}, ["y"] = 7, ["param1"] = 12, ["z"] = 6, ["name"] = "appletree:leaves"}, {["x"] = 3, ["meta"] = {["fields"] = {}, ["inventory"] = {}}, ["y"] = 7, ["param1"] = 13, ["z"] = 7, ["name"] = "appletree:leaves"}, {["x"] = 3, ["meta"] = {["fields"] = {}, ["inventory"] = {}}, ["param2"] = 1, ["y"] = 8, ["param1"] = 13, ["z"] = 0, ["name"] = "appletree:leaves"}, {["x"] = 3, ["meta"] = {["fields"] = {}, ["inventory"] = {}}, ["y"] = 8, ["param1"] = 13, ["z"] = 2, ["name"] = "appletree:leaves"}, {["x"] = 3, ["meta"] = {["fields"] = {}, ["inventory"] = {}}, ["y"] = 8, ["param1"] = 12, ["z"] = 3, ["name"] = "appletree:leaves"}, {["x"] = 3, ["meta"] = {["fields"] = {}, ["inventory"] = {}}, ["y"] = 8, ["param1"] = 12, ["z"] = 5, ["name"] = "appletree:leaves"}, {["x"] = 3, ["meta"] = {["fields"] = {}, ["inventory"] = {}}, ["y"] = 8, ["param1"] = 13, ["z"] = 6, ["name"] = "appletree:leaves"}, {["x"] = 3, ["meta"] = {["fields"] = {}, ["inventory"] = {}}, ["param2"] = 1, ["y"] = 8, ["param1"] = 13, ["z"] = 7, ["name"] = "appletree:leaves"}, {["x"] = 3, ["meta"] = {["fields"] = {}, ["inventory"] = {}}, ["y"] = 9, ["param1"] = 13, ["z"] = 0, ["name"] = "appletree:leaves"}, {["x"] = 3, ["meta"] = {["fields"] = {}, ["inventory"] = {}}, ["y"] = 9, ["param1"] = 13, ["z"] = 3, ["name"] = "appletree:leaves"}, {["x"] = 3, ["meta"] = {["fields"] = {}, ["inventory"] = {}}, ["y"] = 9, ["param1"] = 12, ["z"] = 4, ["name"] = "appletree:leaves"}, {["x"] = 3, ["meta"] = {["fields"] = {}, ["inventory"] = {}}, ["y"] = 9, ["param1"] = 12, ["z"] = 5, ["name"] = "appletree:leaves"}, {["x"] = 3, ["meta"] = {["fields"] = {}, ["inventory"] = {}}, ["y"] = 9, ["param1"] = 13, ["z"] = 6, ["name"] = "appletree:leaves"}, {["x"] = 3, ["meta"] = {["fields"] = {}, ["inventory"] = {}}, ["y"] = 9, ["param1"] = 13, ["z"] = 7, ["name"] = "appletree:leaves"}, {["x"] = 3, ["meta"] = {["fields"] = {}, ["inventory"] = {}}, ["param2"] = 1, ["y"] = 10, ["param1"] = 13, ["z"] = 0, ["name"] = "appletree:leaves"}, {["x"] = 3, ["meta"] = {["fields"] = {}, ["inventory"] = {}}, ["param2"] = 1, ["y"] = 10, ["param1"] = 13, ["z"] = 3, ["name"] = "appletree:leaves"}, {["x"] = 3, ["meta"] = {["fields"] = {}, ["inventory"] = {}}, ["param2"] = 1, ["y"] = 10, ["param1"] = 13, ["z"] = 4, ["name"] = "appletree:leaves"}, {["x"] = 3, ["meta"] = {["fields"] = {}, ["inventory"] = {}}, ["y"] = 10, ["param1"] = 12, ["z"] = 5, ["name"] = "appletree:leaves"}, {["x"] = 3, ["meta"] = {["fields"] = {}, ["inventory"] = {}}, ["param2"] = 1, ["y"] = 10, ["param1"] = 13, ["z"] = 6, ["name"] = "appletree:leaves"}, {["x"] = 3, ["meta"] = {["fields"] = {}, ["inventory"] = {}}, ["param2"] = 1, ["y"] = 11, ["param1"] = 13, ["z"] = 5, ["name"] = "appletree:leaves"}, {["x"] = 3, ["meta"] = {["fields"] = {}, ["inventory"] = {}}, ["param2"] = 1, ["y"] = 11, ["param1"] = 13, ["z"] = 6, ["name"] = "appletree:leaves"}, {["x"] = 4, ["meta"] = {["fields"] = {}, ["inventory"] = {}}, ["y"] = 0, ["param1"] = 11, ["z"] = 3, ["name"] = "doors:trapdoor_open"}, {["x"] = 4, ["meta"] = {["fields"] = {}, ["inventory"] = {}}, ["y"] = 0, ["z"] = 4, ["name"] = "default:dirt_with_grass"}, {["x"] = 4, ["meta"] = {["fields"] = {}, ["inventory"] = {}}, ["y"] = 0, ["z"] = 5, ["name"] = "default:dirt"}, {["x"] = 4, ["meta"] = {["fields"] = {}, ["inventory"] = {}}, ["y"] = 0, ["z"] = 6, ["name"] = "default:dirt_with_grass"}, {["x"] = 4, ["meta"] = {["fields"] = {}, ["inventory"] = {}}, ["param2"] = 2, ["y"] = 0, ["param1"] = 13, ["z"] = 7, ["name"] = "doors:trapdoor_open"}, {["x"] = 4, ["meta"] = {["fields"] = {}, ["inventory"] = {}}, ["param2"] = 1, ["y"] = 5, ["param1"] = 11, ["z"] = 5, ["name"] = "appletree:leaves"}, {["x"] = 4, ["meta"] = {["fields"] = {}, ["inventory"] = {}}, ["param2"] = 1, ["y"] = 6, ["param1"] = 12, ["z"] = 0, ["name"] = "appletree:leaves"}, {["x"] = 4, ["meta"] = {["fields"] = {}, ["inventory"] = {}}, ["param2"] = 1, ["y"] = 6, ["param1"] = 11, ["z"] = 3, ["name"] = "appletree:leaves"}, {["x"] = 4, ["meta"] = {["fields"] = {}, ["inventory"] = {}}, ["y"] = 6, ["param1"] = 11, ["z"] = 4, ["name"] = "appletree:leaves"}, {["x"] = 4, ["meta"] = {["fields"] = {}, ["inventory"] = {}}, ["y"] = 6, ["param1"] = 11, ["z"] = 5, ["name"] = "appletree:leaves"}, {["x"] = 4, ["meta"] = {["fields"] = {}, ["inventory"] = {}}, ["y"] = 6, ["param1"] = 12, ["z"] = 6, ["name"] = "appletree:leaves"}, {["x"] = 4, ["meta"] = {["fields"] = {}, ["inventory"] = {}}, ["y"] = 6, ["param1"] = 13, ["z"] = 7, ["name"] = "appletree:leaves"}, {["x"] = 4, ["meta"] = {["fields"] = {}, ["inventory"] = {}}, ["param2"] = 1, ["y"] = 7, ["param1"] = 12, ["z"] = 0, ["name"] = "appletree:leaves"}, {["x"] = 4, ["meta"] = {["fields"] = {}, ["inventory"] = {}}, ["param2"] = 1, ["y"] = 7, ["param1"] = 13, ["z"] = 1, ["name"] = "appletree:leaves"}, {["x"] = 4, ["meta"] = {["fields"] = {}, ["inventory"] = {}}, ["y"] = 7, ["param1"] = 12, ["z"] = 2, ["name"] = "appletree:leaves"}, {["x"] = 4, ["meta"] = {["fields"] = {}, ["inventory"] = {}}, ["y"] = 7, ["param1"] = 11, ["z"] = 3, ["name"] = "appletree:leaves"}, {["x"] = 4, ["meta"] = {["fields"] = {}, ["inventory"] = {}}, ["y"] = 7, ["param1"] = 11, ["z"] = 4, ["name"] = "appletree:leaves"}, {["x"] = 4, ["meta"] = {["fields"] = {}, ["inventory"] = {}}, ["y"] = 7, ["param1"] = 11, ["z"] = 5, ["name"] = "appletree:leaves"}, {["x"] = 4, ["meta"] = {["fields"] = {}, ["inventory"] = {}}, ["y"] = 7, ["param1"] = 12, ["z"] = 6, ["name"] = "appletree:leaves"}, {["x"] = 4, ["meta"] = {["fields"] = {}, ["inventory"] = {}}, ["y"] = 7, ["param1"] = 13, ["z"] = 7, ["name"] = "appletree:leaves"}, {["x"] = 4, ["meta"] = {["fields"] = {}, ["inventory"] = {}}, ["y"] = 8, ["param1"] = 12, ["z"] = 0, ["name"] = "appletree:leaves"}, {["x"] = 4, ["meta"] = {["fields"] = {}, ["inventory"] = {}}, ["param2"] = 1, ["y"] = 8, ["param1"] = 13, ["z"] = 1, ["name"] = "appletree:leaves"}, {["x"] = 4, ["meta"] = {["fields"] = {}, ["inventory"] = {}}, ["param2"] = 1, ["y"] = 8, ["param1"] = 12, ["z"] = 2, ["name"] = "appletree:leaves"}, {["x"] = 4, ["meta"] = {["fields"] = {}, ["inventory"] = {}}, ["y"] = 8, ["param1"] = 11, ["z"] = 3, ["name"] = "appletree:leaves"}, {["x"] = 4, ["meta"] = {["fields"] = {}, ["inventory"] = {}}, ["y"] = 8, ["param1"] = 11, ["z"] = 4, ["name"] = "appletree:leaves"}, {["x"] = 4, ["meta"] = {["fields"] = {}, ["inventory"] = {}}, ["y"] = 8, ["param1"] = 13, ["z"] = 7, ["name"] = "appletree:leaves"}, {["x"] = 4, ["meta"] = {["fields"] = {}, ["inventory"] = {}}, ["y"] = 9, ["param1"] = 13, ["z"] = 0, ["name"] = "appletree:leaves"}, {["x"] = 4, ["meta"] = {["fields"] = {}, ["inventory"] = {}}, ["y"] = 9, ["param1"] = 13, ["z"] = 2, ["name"] = "appletree:leaves"}, {["x"] = 4, ["meta"] = {["fields"] = {}, ["inventory"] = {}}, ["y"] = 9, ["param1"] = 12, ["z"] = 3, ["name"] = "appletree:leaves"}, {["x"] = 4, ["meta"] = {["fields"] = {}, ["inventory"] = {}}, ["y"] = 9, ["param1"] = 12, ["z"] = 4, ["name"] = "appletree:leaves"}, {["x"] = 4, ["meta"] = {["fields"] = {}, ["inventory"] = {}}, ["y"] = 9, ["param1"] = 11, ["z"] = 5, ["name"] = "appletree:leaves"}, {["x"] = 4, ["meta"] = {["fields"] = {}, ["inventory"] = {}}, ["y"] = 9, ["param1"] = 12, ["z"] = 6, ["name"] = "appletree:leaves"}, {["x"] = 4, ["meta"] = {["fields"] = {}, ["inventory"] = {}}, ["y"] = 9, ["param1"] = 13, ["z"] = 7, ["name"] = "appletree:leaves"}, {["x"] = 4, ["meta"] = {["fields"] = {}, ["inventory"] = {}}, ["y"] = 10, ["param1"] = 13, ["z"] = 3, ["name"] = "appletree:leaves"}, {["x"] = 4, ["meta"] = {["fields"] = {}, ["inventory"] = {}}, ["y"] = 10, ["param1"] = 13, ["z"] = 4, ["name"] = "appletree:leaves"}, {["x"] = 4, ["meta"] = {["fields"] = {}, ["inventory"] = {}}, ["y"] = 10, ["param1"] = 12, ["z"] = 5, ["name"] = "appletree:leaves"}, {["x"] = 4, ["meta"] = {["fields"] = {}, ["inventory"] = {}}, ["y"] = 10, ["param1"] = 12, ["z"] = 6, ["name"] = "appletree:leaves"}, {["x"] = 4, ["meta"] = {["fields"] = {}, ["inventory"] = {}}, ["param2"] = 1, ["y"] = 10, ["param1"] = 13, ["z"] = 7, ["name"] = "appletree:leaves"}, {["x"] = 4, ["meta"] = {["fields"] = {}, ["inventory"] = {}}, ["param2"] = 1, ["y"] = 11, ["param1"] = 13, ["z"] = 3, ["name"] = "appletree:leaves"}, {["x"] = 4, ["meta"] = {["fields"] = {}, ["inventory"] = {}}, ["param2"] = 1, ["y"] = 11, ["param1"] = 13, ["z"] = 5, ["name"] = "appletree:leaves"}, {["x"] = 4, ["meta"] = {["fields"] = {}, ["inventory"] = {}}, ["param2"] = 1, ["y"] = 11, ["param1"] = 13, ["z"] = 6, ["name"] = "appletree:leaves"}, {["x"] = 5, ["meta"] = {["fields"] = {}, ["inventory"] = {}}, ["y"] = 0, ["param1"] = 10, ["z"] = 3, ["name"] = "doors:trapdoor_open"}, {["x"] = 5, ["meta"] = {["fields"] = {}, ["inventory"] = {}}, ["y"] = 0, ["z"] = 4, ["name"] = "default:dirt_with_grass"}, {["x"] = 5, ["meta"] = {["fields"] = {}, ["inventory"] = {}}, ["y"] = 0, ["z"] = 5, ["name"] = "default:dirt"}, {["x"] = 5, ["meta"] = {["fields"] = {}, ["inventory"] = {}}, ["y"] = 0, ["z"] = 6, ["name"] = "default:dirt_with_grass"}, {["x"] = 5, ["meta"] = {["fields"] = {}, ["inventory"] = {}}, ["param2"] = 2, ["y"] = 0, ["param1"] = 13, ["z"] = 7, ["name"] = "doors:trapdoor_open"}, {["x"] = 5, ["meta"] = {["fields"] = {}, ["inventory"] = {}}, ["y"] = 1, ["z"] = 5, ["name"] = "birch:tree"}, {["x"] = 5, ["meta"] = {["fields"] = {}, ["inventory"] = {}}, ["y"] = 2, ["z"] = 5, ["name"] = "birch:tree"}, {["x"] = 5, ["meta"] = {["fields"] = {}, ["inventory"] = {}}, ["y"] = 3, ["z"] = 5, ["name"] = "birch:tree"}, {["x"] = 5, ["meta"] = {["fields"] = {}, ["inventory"] = {}}, ["y"] = 4, ["z"] = 5, ["name"] = "birch:tree"}, {["x"] = 5, ["meta"] = {["fields"] = {}, ["inventory"] = {}}, ["param2"] = 1, ["y"] = 5, ["param1"] = 10, ["z"] = 4, ["name"] = "appletree:leaves"}, {["x"] = 5, ["meta"] = {["fields"] = {}, ["inventory"] = {}}, ["param2"] = 20, ["y"] = 5, ["z"] = 5, ["name"] = "birch:tree"}, {["x"] = 5, ["meta"] = {["fields"] = {}, ["inventory"] = {}}, ["param2"] = 1, ["y"] = 5, ["param1"] = 12, ["z"] = 6, ["name"] = "appletree:leaves"}, {["x"] = 5, ["meta"] = {["fields"] = {}, ["inventory"] = {}}, ["param2"] = 1, ["y"] = 6, ["param1"] = 11, ["z"] = 0, ["name"] = "appletree:leaves"}, {["x"] = 5, ["meta"] = {["fields"] = {}, ["inventory"] = {}}, ["y"] = 6, ["param1"] = 10, ["z"] = 4, ["name"] = "appletree:leaves"}, {["x"] = 5, ["meta"] = {["fields"] = {}, ["inventory"] = {}}, ["param2"] = 20, ["y"] = 6, ["z"] = 5, ["name"] = "birch:tree"}, {["x"] = 5, ["meta"] = {["fields"] = {}, ["inventory"] = {}}, ["y"] = 6, ["param1"] = 12, ["z"] = 6, ["name"] = "appletree:leaves"}, {["x"] = 5, ["meta"] = {["fields"] = {}, ["inventory"] = {}}, ["y"] = 6, ["param1"] = 13, ["z"] = 7, ["name"] = "appletree:leaves"}, {["x"] = 5, ["meta"] = {["fields"] = {}, ["inventory"] = {}}, ["param2"] = 1, ["y"] = 7, ["param1"] = 11, ["z"] = 0, ["name"] = "appletree:leaves"}, {["x"] = 5, ["meta"] = {["fields"] = {}, ["inventory"] = {}}, ["param2"] = 1, ["y"] = 7, ["param1"] = 11, ["z"] = 2, ["name"] = "appletree:leaves"}, {["x"] = 5, ["meta"] = {["fields"] = {}, ["inventory"] = {}}, ["y"] = 7, ["param1"] = 10, ["z"] = 3, ["name"] = "appletree:leaves"}, {["x"] = 5, ["meta"] = {["fields"] = {}, ["inventory"] = {}}, ["y"] = 7, ["param1"] = 10, ["z"] = 4, ["name"] = "appletree:leaves"}, {["x"] = 5, ["meta"] = {["fields"] = {}, ["inventory"] = {}}, ["param2"] = 20, ["y"] = 7, ["z"] = 5, ["name"] = "birch:tree"}, {["x"] = 5, ["meta"] = {["fields"] = {}, ["inventory"] = {}}, ["y"] = 7, ["param1"] = 12, ["z"] = 6, ["name"] = "appletree:leaves"}, {["x"] = 5, ["meta"] = {["fields"] = {}, ["inventory"] = {}}, ["y"] = 7, ["param1"] = 13, ["z"] = 7, ["name"] = "appletree:leaves"}, {["x"] = 5, ["meta"] = {["fields"] = {}, ["inventory"] = {}}, ["param2"] = 1, ["y"] = 8, ["param1"] = 12, ["z"] = 0, ["name"] = "appletree:leaves"}, {["x"] = 5, ["meta"] = {["fields"] = {}, ["inventory"] = {}}, ["param2"] = 1, ["y"] = 8, ["param1"] = 12, ["z"] = 1, ["name"] = "appletree:leaves"}, {["x"] = 5, ["meta"] = {["fields"] = {}, ["inventory"] = {}}, ["y"] = 8, ["param1"] = 11, ["z"] = 2, ["name"] = "appletree:leaves"}, {["x"] = 5, ["meta"] = {["fields"] = {}, ["inventory"] = {}}, ["y"] = 8, ["param1"] = 11, ["z"] = 3, ["name"] = "appletree:leaves"}, {["x"] = 5, ["meta"] = {["fields"] = {}, ["inventory"] = {}}, ["y"] = 8, ["param1"] = 10, ["z"] = 4, ["name"] = "appletree:leaves"}, {["x"] = 5, ["meta"] = {["fields"] = {}, ["inventory"] = {}}, ["param2"] = 20, ["y"] = 8, ["z"] = 5, ["name"] = "birch:tree"}, {["x"] = 5, ["meta"] = {["fields"] = {}, ["inventory"] = {}}, ["y"] = 9, ["param1"] = 13, ["z"] = 0, ["name"] = "appletree:leaves"}, {["x"] = 5, ["meta"] = {["fields"] = {}, ["inventory"] = {}}, ["param2"] = 1, ["y"] = 9, ["param1"] = 13, ["z"] = 1, ["name"] = "appletree:leaves"}, {["x"] = 5, ["meta"] = {["fields"] = {}, ["inventory"] = {}}, ["y"] = 9, ["param1"] = 12, ["z"] = 2, ["name"] = "appletree:leaves"}, {["x"] = 5, ["meta"] = {["fields"] = {}, ["inventory"] = {}}, ["y"] = 9, ["param1"] = 12, ["z"] = 3, ["name"] = "appletree:leaves"}, {["x"] = 5, ["meta"] = {["fields"] = {}, ["inventory"] = {}}, ["y"] = 9, ["param1"] = 11, ["z"] = 4, ["name"] = "appletree:leaves"}, {["x"] = 5, ["meta"] = {["fields"] = {}, ["inventory"] = {}}, ["y"] = 9, ["param1"] = 11, ["z"] = 5, ["name"] = "appletree:leaves"}, {["x"] = 5, ["meta"] = {["fields"] = {}, ["inventory"] = {}}, ["y"] = 9, ["param1"] = 12, ["z"] = 6, ["name"] = "appletree:leaves"}, {["x"] = 5, ["meta"] = {["fields"] = {}, ["inventory"] = {}}, ["param2"] = 1, ["y"] = 10, ["param1"] = 13, ["z"] = 2, ["name"] = "appletree:leaves"}, {["x"] = 5, ["meta"] = {["fields"] = {}, ["inventory"] = {}}, ["param2"] = 1, ["y"] = 10, ["param1"] = 13, ["z"] = 3, ["name"] = "appletree:leaves"}, {["x"] = 5, ["meta"] = {["fields"] = {}, ["inventory"] = {}}, ["y"] = 10, ["param1"] = 12, ["z"] = 4, ["name"] = "appletree:leaves"}, {["x"] = 5, ["meta"] = {["fields"] = {}, ["inventory"] = {}}, ["y"] = 10, ["param1"] = 12, ["z"] = 5, ["name"] = "appletree:leaves"}, {["x"] = 5, ["meta"] = {["fields"] = {}, ["inventory"] = {}}, ["param2"] = 1, ["y"] = 10, ["param1"] = 12, ["z"] = 6, ["name"] = "appletree:leaves"}, {["x"] = 5, ["meta"] = {["fields"] = {}, ["inventory"] = {}}, ["y"] = 10, ["param1"] = 13, ["z"] = 7, ["name"] = "appletree:leaves"}, {["x"] = 5, ["meta"] = {["fields"] = {}, ["inventory"] = {}}, ["param2"] = 1, ["y"] = 11, ["param1"] = 13, ["z"] = 4, ["name"] = "appletree:leaves"}, {["x"] = 5, ["meta"] = {["fields"] = {}, ["inventory"] = {}}, ["param2"] = 1, ["y"] = 11, ["param1"] = 13, ["z"] = 5, ["name"] = "appletree:leaves"}, {["x"] = 5, ["meta"] = {["fields"] = {}, ["inventory"] = {}}, ["param2"] = 1, ["y"] = 11, ["param1"] = 13, ["z"] = 6, ["name"] = "appletree:leaves"}, {["x"] = 5, ["meta"] = {["fields"] = {}, ["inventory"] = {}}, ["param2"] = 1, ["y"] = 11, ["param1"] = 13, ["z"] = 7, ["name"] = "appletree:leaves"}, {["x"] = 6, ["meta"] = {["fields"] = {}, ["inventory"] = {}}, ["y"] = 0, ["param1"] = 10, ["z"] = 3, ["name"] = "doors:trapdoor_open"}, {["x"] = 6, ["meta"] = {["fields"] = {}, ["inventory"] = {}}, ["y"] = 0, ["z"] = 4, ["name"] = "default:dirt_with_grass"}, {["x"] = 6, ["meta"] = {["fields"] = {}, ["inventory"] = {}}, ["y"] = 0, ["z"] = 5, ["name"] = "default:dirt"}, {["x"] = 6, ["meta"] = {["fields"] = {}, ["inventory"] = {}}, ["y"] = 0, ["z"] = 6, ["name"] = "default:dirt"}, {["x"] = 6, ["meta"] = {["fields"] = {}, ["inventory"] = {}}, ["param2"] = 2, ["y"] = 0, ["param1"] = 13, ["z"] = 7, ["name"] = "doors:trapdoor_open"}, {["x"] = 6, ["meta"] = {["fields"] = {}, ["inventory"] = {}}, ["param2"] = 1, ["y"] = 5, ["param1"] = 11, ["z"] = 5, ["name"] = "appletree:leaves"}, {["x"] = 6, ["meta"] = {["fields"] = {}, ["inventory"] = {}}, ["param2"] = 1, ["y"] = 5, ["param1"] = 12, ["z"] = 6, ["name"] = "appletree:leaves"}, {["x"] = 6, ["meta"] = {["fields"] = {}, ["inventory"] = {}}, ["y"] = 6, ["param1"] = 11, ["z"] = 0, ["name"] = "appletree:leaves"}, {["x"] = 6, ["meta"] = {["fields"] = {}, ["inventory"] = {}}, ["param2"] = 1, ["y"] = 6, ["param1"] = 10, ["z"] = 3, ["name"] = "appletree:leaves"}, {["x"] = 6, ["meta"] = {["fields"] = {}, ["inventory"] = {}}, ["y"] = 6, ["param1"] = 10, ["z"] = 4, ["name"] = "appletree:leaves"}, {["x"] = 6, ["meta"] = {["fields"] = {}, ["inventory"] = {}}, ["y"] = 6, ["param1"] = 11, ["z"] = 5, ["name"] = "appletree:leaves"}, {["x"] = 6, ["meta"] = {["fields"] = {}, ["inventory"] = {}}, ["y"] = 6, ["param1"] = 12, ["z"] = 6, ["name"] = "appletree:leaves"}, {["x"] = 6, ["meta"] = {["fields"] = {}, ["inventory"] = {}}, ["param2"] = 1, ["y"] = 6, ["param1"] = 13, ["z"] = 7, ["name"] = "appletree:leaves"}, {["x"] = 6, ["meta"] = {["fields"] = {}, ["inventory"] = {}}, ["y"] = 7, ["param1"] = 11, ["z"] = 0, ["name"] = "appletree:leaves"}, {["x"] = 6, ["meta"] = {["fields"] = {}, ["inventory"] = {}}, ["param2"] = 1, ["y"] = 7, ["param1"] = 12, ["z"] = 1, ["name"] = "appletree:leaves"}, {["x"] = 6, ["meta"] = {["fields"] = {}, ["inventory"] = {}}, ["param2"] = 1, ["y"] = 7, ["param1"] = 11, ["z"] = 2, ["name"] = "appletree:leaves"}, {["x"] = 6, ["meta"] = {["fields"] = {}, ["inventory"] = {}}, ["y"] = 7, ["param1"] = 10, ["z"] = 3, ["name"] = "appletree:leaves"}, {["x"] = 6, ["meta"] = {["fields"] = {}, ["inventory"] = {}}, ["y"] = 7, ["param1"] = 10, ["z"] = 4, ["name"] = "appletree:leaves"}, {["x"] = 6, ["meta"] = {["fields"] = {}, ["inventory"] = {}}, ["y"] = 7, ["param1"] = 11, ["z"] = 5, ["name"] = "appletree:leaves"}, {["x"] = 6, ["meta"] = {["fields"] = {}, ["inventory"] = {}}, ["y"] = 7, ["param1"] = 12, ["z"] = 6, ["name"] = "appletree:leaves"}, {["x"] = 6, ["meta"] = {["fields"] = {}, ["inventory"] = {}}, ["y"] = 7, ["param1"] = 13, ["z"] = 7, ["name"] = "appletree:leaves"}, {["x"] = 6, ["meta"] = {["fields"] = {}, ["inventory"] = {}}, ["y"] = 8, ["param1"] = 12, ["z"] = 0, ["name"] = "appletree:leaves"}, {["x"] = 6, ["meta"] = {["fields"] = {}, ["inventory"] = {}}, ["param2"] = 1, ["y"] = 8, ["param1"] = 12, ["z"] = 1, ["name"] = "appletree:leaves"}, {["x"] = 6, ["meta"] = {["fields"] = {}, ["inventory"] = {}}, ["param2"] = 1, ["y"] = 8, ["param1"] = 12, ["z"] = 2, ["name"] = "appletree:leaves"}, {["x"] = 6, ["meta"] = {["fields"] = {}, ["inventory"] = {}}, ["y"] = 8, ["param1"] = 11, ["z"] = 3, ["name"] = "appletree:leaves"}, {["x"] = 6, ["meta"] = {["fields"] = {}, ["inventory"] = {}}, ["y"] = 8, ["param1"] = 11, ["z"] = 5, ["name"] = "appletree:leaves"}, {["x"] = 6, ["meta"] = {["fields"] = {}, ["inventory"] = {}}, ["y"] = 8, ["param1"] = 12, ["z"] = 6, ["name"] = "appletree:leaves"}, {["x"] = 6, ["meta"] = {["fields"] = {}, ["inventory"] = {}}, ["param2"] = 1, ["y"] = 9, ["param1"] = 13, ["z"] = 0, ["name"] = "appletree:leaves"}, {["x"] = 6, ["meta"] = {["fields"] = {}, ["inventory"] = {}}, ["param2"] = 1, ["y"] = 9, ["param1"] = 13, ["z"] = 1, ["name"] = "appletree:leaves"}, {["x"] = 6, ["meta"] = {["fields"] = {}, ["inventory"] = {}}, ["param2"] = 1, ["y"] = 9, ["param1"] = 13, ["z"] = 2, ["name"] = "appletree:leaves"}, {["x"] = 6, ["meta"] = {["fields"] = {}, ["inventory"] = {}}, ["y"] = 9, ["param1"] = 12, ["z"] = 3, ["name"] = "appletree:leaves"}, {["x"] = 6, ["meta"] = {["fields"] = {}, ["inventory"] = {}}, ["y"] = 9, ["param1"] = 12, ["z"] = 4, ["name"] = "appletree:leaves"}, {["x"] = 6, ["meta"] = {["fields"] = {}, ["inventory"] = {}}, ["y"] = 9, ["param1"] = 12, ["z"] = 5, ["name"] = "appletree:leaves"}, {["x"] = 6, ["meta"] = {["fields"] = {}, ["inventory"] = {}}, ["y"] = 9, ["param1"] = 13, ["z"] = 7, ["name"] = "appletree:leaves"}, {["x"] = 6, ["meta"] = {["fields"] = {}, ["inventory"] = {}}, ["y"] = 10, ["param1"] = 13, ["z"] = 3, ["name"] = "appletree:leaves"}, {["x"] = 6, ["meta"] = {["fields"] = {}, ["inventory"] = {}}, ["param2"] = 1, ["y"] = 10, ["param1"] = 13, ["z"] = 4, ["name"] = "appletree:leaves"}, {["x"] = 6, ["meta"] = {["fields"] = {}, ["inventory"] = {}}, ["y"] = 10, ["param1"] = 12, ["z"] = 5, ["name"] = "appletree:leaves"}, {["x"] = 6, ["meta"] = {["fields"] = {}, ["inventory"] = {}}, ["y"] = 10, ["param1"] = 13, ["z"] = 6, ["name"] = "appletree:leaves"}, {["x"] = 6, ["meta"] = {["fields"] = {}, ["inventory"] = {}}, ["y"] = 10, ["param1"] = 13, ["z"] = 7, ["name"] = "appletree:leaves"}, {["x"] = 6, ["meta"] = {["fields"] = {}, ["inventory"] = {}}, ["param2"] = 1, ["y"] = 11, ["param1"] = 13, ["z"] = 3, ["name"] = "appletree:leaves"}, {["x"] = 6, ["meta"] = {["fields"] = {}, ["inventory"] = {}}, ["param2"] = 1, ["y"] = 11, ["param1"] = 13, ["z"] = 5, ["name"] = "appletree:leaves"}, {["x"] = 6, ["meta"] = {["fields"] = {}, ["inventory"] = {}}, ["param2"] = 1, ["y"] = 11, ["param1"] = 13, ["z"] = 6, ["name"] = "appletree:leaves"}, {["x"] = 6, ["meta"] = {["fields"] = {}, ["inventory"] = {}}, ["param2"] = 1, ["y"] = 11, ["param1"] = 13, ["z"] = 7, ["name"] = "appletree:leaves"}, {["x"] = 7, ["meta"] = {["fields"] = {}, ["inventory"] = {}}, ["param2"] = 3, ["y"] = 0, ["param1"] = 11, ["z"] = 4, ["name"] = "doors:trapdoor_open"}, {["x"] = 7, ["meta"] = {["fields"] = {}, ["inventory"] = {}}, ["param2"] = 3, ["y"] = 0, ["param1"] = 11, ["z"] = 5, ["name"] = "doors:trapdoor_open"}, {["x"] = 7, ["meta"] = {["fields"] = {}, ["inventory"] = {}}, ["param2"] = 3, ["y"] = 0, ["param1"] = 12, ["z"] = 6, ["name"] = "doors:trapdoor_open"}, {["x"] = 7, ["meta"] = {["fields"] = {}, ["inventory"] = {}}, ["y"] = 6, ["param1"] = 11, ["z"] = 3, ["name"] = "appletree:leaves"}, {["x"] = 7, ["meta"] = {["fields"] = {}, ["inventory"] = {}}, ["y"] = 6, ["param1"] = 11, ["z"] = 4, ["name"] = "appletree:leaves"}, {["x"] = 7, ["meta"] = {["fields"] = {}, ["inventory"] = {}}, ["param2"] = 1, ["y"] = 6, ["param1"] = 12, ["z"] = 6, ["name"] = "appletree:leaves"}, {["x"] = 7, ["meta"] = {["fields"] = {}, ["inventory"] = {}}, ["param2"] = 1, ["y"] = 6, ["param1"] = 13, ["z"] = 7, ["name"] = "appletree:leaves"}, {["x"] = 7, ["meta"] = {["fields"] = {}, ["inventory"] = {}}, ["y"] = 7, ["param1"] = 12, ["z"] = 0, ["name"] = "appletree:leaves"}, {["x"] = 7, ["meta"] = {["fields"] = {}, ["inventory"] = {}}, ["param2"] = 1, ["y"] = 7, ["param1"] = 12, ["z"] = 2, ["name"] = "appletree:leaves"}, {["x"] = 7, ["meta"] = {["fields"] = {}, ["inventory"] = {}}, ["y"] = 7, ["param1"] = 11, ["z"] = 3, ["name"] = "appletree:leaves"}, {["x"] = 7, ["meta"] = {["fields"] = {}, ["inventory"] = {}}, ["y"] = 7, ["param1"] = 11, ["z"] = 4, ["name"] = "appletree:leaves"}, {["x"] = 7, ["meta"] = {["fields"] = {}, ["inventory"] = {}}, ["y"] = 7, ["param1"] = 11, ["z"] = 5, ["name"] = "appletree:leaves"}, {["x"] = 7, ["meta"] = {["fields"] = {}, ["inventory"] = {}}, ["y"] = 7, ["param1"] = 12, ["z"] = 6, ["name"] = "appletree:leaves"}, {["x"] = 7, ["meta"] = {["fields"] = {}, ["inventory"] = {}}, ["y"] = 7, ["param1"] = 13, ["z"] = 7, ["name"] = "appletree:leaves"}, {["x"] = 7, ["meta"] = {["fields"] = {}, ["inventory"] = {}}, ["param2"] = 1, ["y"] = 8, ["param1"] = 12, ["z"] = 0, ["name"] = "appletree:leaves"}, {["x"] = 7, ["meta"] = {["fields"] = {}, ["inventory"] = {}}, ["param2"] = 1, ["y"] = 8, ["param1"] = 13, ["z"] = 1, ["name"] = "appletree:leaves"}, {["x"] = 7, ["meta"] = {["fields"] = {}, ["inventory"] = {}}, ["param2"] = 1, ["y"] = 8, ["param1"] = 12, ["z"] = 2, ["name"] = "appletree:leaves"}, {["x"] = 7, ["meta"] = {["fields"] = {}, ["inventory"] = {}}, ["param2"] = 1, ["y"] = 8, ["param1"] = 11, ["z"] = 3, ["name"] = "appletree:leaves"}, {["x"] = 7, ["meta"] = {["fields"] = {}, ["inventory"] = {}}, ["param2"] = 1, ["y"] = 8, ["param1"] = 11, ["z"] = 4, ["name"] = "appletree:leaves"}, {["x"] = 7, ["meta"] = {["fields"] = {}, ["inventory"] = {}}, ["y"] = 8, ["param1"] = 12, ["z"] = 5, ["name"] = "appletree:leaves"}, {["x"] = 7, ["meta"] = {["fields"] = {}, ["inventory"] = {}}, ["param2"] = 1, ["y"] = 8, ["param1"] = 13, ["z"] = 6, ["name"] = "appletree:leaves"}, {["x"] = 7, ["meta"] = {["fields"] = {}, ["inventory"] = {}}, ["y"] = 8, ["param1"] = 13, ["z"] = 7, ["name"] = "appletree:leaves"}, {["x"] = 7, ["meta"] = {["fields"] = {}, ["inventory"] = {}}, ["param2"] = 1, ["y"] = 9, ["param1"] = 13, ["z"] = 0, ["name"] = "appletree:leaves"}, {["x"] = 7, ["meta"] = {["fields"] = {}, ["inventory"] = {}}, ["param2"] = 1, ["y"] = 9, ["param1"] = 13, ["z"] = 2, ["name"] = "appletree:leaves"}, {["x"] = 7, ["meta"] = {["fields"] = {}, ["inventory"] = {}}, ["param2"] = 1, ["y"] = 9, ["param1"] = 12, ["z"] = 3, ["name"] = "appletree:leaves"}, {["x"] = 7, ["meta"] = {["fields"] = {}, ["inventory"] = {}}, ["y"] = 9, ["param1"] = 12, ["z"] = 4, ["name"] = "appletree:leaves"}, {["x"] = 7, ["meta"] = {["fields"] = {}, ["inventory"] = {}}, ["y"] = 9, ["param1"] = 13, ["z"] = 5, ["name"] = "appletree:leaves"}, {["x"] = 7, ["meta"] = {["fields"] = {}, ["inventory"] = {}}, ["param2"] = 1, ["y"] = 9, ["param1"] = 13, ["z"] = 7, ["name"] = "appletree:leaves"}, {["x"] = 7, ["meta"] = {["fields"] = {}, ["inventory"] = {}}, ["y"] = 10, ["param1"] = 13, ["z"] = 0, ["name"] = "appletree:leaves"}, {["x"] = 7, ["meta"] = {["fields"] = {}, ["inventory"] = {}}, ["y"] = 10, ["param1"] = 13, ["z"] = 2, ["name"] = "appletree:leaves"}, {["x"] = 7, ["meta"] = {["fields"] = {}, ["inventory"] = {}}, ["y"] = 10, ["param1"] = 13, ["z"] = 3, ["name"] = "appletree:leaves"}, {["x"] = 7, ["meta"] = {["fields"] = {}, ["inventory"] = {}}, ["y"] = 10, ["param1"] = 12, ["z"] = 4, ["name"] = "appletree:leaves"}, {["x"] = 7, ["meta"] = {["fields"] = {}, ["inventory"] = {}}, ["param2"] = 1, ["y"] = 10, ["param1"] = 13, ["z"] = 5, ["name"] = "appletree:leaves"}, {["x"] = 7, ["meta"] = {["fields"] = {}, ["inventory"] = {}}, ["y"] = 10, ["param1"] = 13, ["z"] = 7, ["name"] = "appletree:leaves"}, {["x"] = 7, ["meta"] = {["fields"] = {}, ["inventory"] = {}}, ["param2"] = 1, ["y"] = 11, ["param1"] = 13, ["z"] = 4, ["name"] = "appletree:leaves"}, {["x"] = 7, ["meta"] = {["fields"] = {}, ["inventory"] = {}}, ["param2"] = 1, ["y"] = 11, ["param1"] = 13, ["z"] = 5, ["name"] = "appletree:leaves"}, {["x"] = 8, ["meta"] = {["fields"] = {}, ["inventory"] = {}}, ["y"] = 6, ["param1"] = 12, ["z"] = 4, ["name"] = "appletree:leaves"}, {["x"] = 8, ["meta"] = {["fields"] = {}, ["inventory"] = {}}, ["y"] = 7, ["param1"] = 12, ["z"] = 3, ["name"] = "appletree:leaves"}, {["x"] = 8, ["meta"] = {["fields"] = {}, ["inventory"] = {}}, ["y"] = 7, ["param1"] = 12, ["z"] = 4, ["name"] = "appletree:leaves"}, {["x"] = 8, ["meta"] = {["fields"] = {}, ["inventory"] = {}}, ["y"] = 7, ["param1"] = 12, ["z"] = 5, ["name"] = "appletree:leaves"}, {["x"] = 8, ["meta"] = {["fields"] = {}, ["inventory"] = {}}, ["param2"] = 1, ["y"] = 7, ["param1"] = 12, ["z"] = 6, ["name"] = "appletree:leaves"}, {["x"] = 8, ["meta"] = {["fields"] = {}, ["inventory"] = {}}, ["y"] = 7, ["param1"] = 13, ["z"] = 7, ["name"] = "appletree:leaves"}, {["x"] = 8, ["meta"] = {["fields"] = {}, ["inventory"] = {}}, ["param2"] = 1, ["y"] = 8, ["param1"] = 13, ["z"] = 2, ["name"] = "appletree:leaves"}, {["x"] = 8, ["meta"] = {["fields"] = {}, ["inventory"] = {}}, ["param2"] = 1, ["y"] = 8, ["param1"] = 12, ["z"] = 3, ["name"] = "appletree:leaves"}, {["x"] = 8, ["meta"] = {["fields"] = {}, ["inventory"] = {}}, ["param2"] = 1, ["y"] = 8, ["param1"] = 12, ["z"] = 4, ["name"] = "appletree:leaves"}, {["x"] = 8, ["meta"] = {["fields"] = {}, ["inventory"] = {}}, ["y"] = 8, ["param1"] = 12, ["z"] = 5, ["name"] = "appletree:leaves"}, {["x"] = 8, ["meta"] = {["fields"] = {}, ["inventory"] = {}}, ["param2"] = 1, ["y"] = 8, ["param1"] = 12, ["z"] = 6, ["name"] = "appletree:leaves"}, {["x"] = 8, ["meta"] = {["fields"] = {}, ["inventory"] = {}}, ["y"] = 8, ["param1"] = 13, ["z"] = 7, ["name"] = "appletree:leaves"}, {["x"] = 8, ["meta"] = {["fields"] = {}, ["inventory"] = {}}, ["y"] = 9, ["param1"] = 13, ["z"] = 0, ["name"] = "appletree:leaves"}, {["x"] = 8, ["meta"] = {["fields"] = {}, ["inventory"] = {}}, ["param2"] = 1, ["y"] = 9, ["param1"] = 13, ["z"] = 2, ["name"] = "appletree:leaves"}, {["x"] = 8, ["meta"] = {["fields"] = {}, ["inventory"] = {}}, ["y"] = 9, ["param1"] = 13, ["z"] = 3, ["name"] = "appletree:leaves"}, {["x"] = 8, ["meta"] = {["fields"] = {}, ["inventory"] = {}}, ["param2"] = 1, ["y"] = 9, ["param1"] = 13, ["z"] = 4, ["name"] = "appletree:leaves"}, {["x"] = 8, ["meta"] = {["fields"] = {}, ["inventory"] = {}}, ["param2"] = 1, ["y"] = 9, ["param1"] = 13, ["z"] = 5, ["name"] = "appletree:leaves"}, {["x"] = 8, ["meta"] = {["fields"] = {}, ["inventory"] = {}}, ["y"] = 9, ["param1"] = 13, ["z"] = 6, ["name"] = "appletree:leaves"}, {["x"] = 8, ["meta"] = {["fields"] = {}, ["inventory"] = {}}, ["y"] = 9, ["param1"] = 13, ["z"] = 7, ["name"] = "appletree:leaves"}, {["x"] = 8, ["meta"] = {["fields"] = {}, ["inventory"] = {}}, ["y"] = 10, ["param1"] = 13, ["z"] = 0, ["name"] = "appletree:leaves"}, {["x"] = 8, ["meta"] = {["fields"] = {}, ["inventory"] = {}}, ["y"] = 10, ["param1"] = 13, ["z"] = 2, ["name"] = "appletree:leaves"}, {["x"] = 8, ["meta"] = {["fields"] = {}, ["inventory"] = {}}, ["y"] = 10, ["param1"] = 13, ["z"] = 3, ["name"] = "appletree:leaves"}, {["x"] = 8, ["meta"] = {["fields"] = {}, ["inventory"] = {}}, ["param2"] = 1, ["y"] = 10, ["param1"] = 13, ["z"] = 4, ["name"] = "appletree:leaves"}, {["x"] = 8, ["meta"] = {["fields"] = {}, ["inventory"] = {}}, ["y"] = 10, ["param1"] = 13, ["z"] = 5, ["name"] = "appletree:leaves"}, {["x"] = 8, ["meta"] = {["fields"] = {}, ["inventory"] = {}}, ["y"] = 10, ["param1"] = 13, ["z"] = 7, ["name"] = "appletree:leaves"}}