5:return {{["x"] = 0, ["meta"] = {["fields"] = {}, ["inventory"] = {}}, ["param2"] = 18, ["y"] = 0, ["z"] = 12, ["name"] = "default:pinetree"}, {["x"] = 0, ["meta"] = {["fields"] = {["infotext"] = "Chest", ["chest_inv_ver"] = "2", ["formspec"] = "size[8,9]bgcolor[#080808BB;true]background[5,5;1,1;gui_formbg.png;true]listcolors[#00000069;#5A5A5A;#141318;#30434C;#FFF]list[current_name;main;0,0.3;8,4;]list[current_player;main;0,4.85;8,1;]list[current_player;main;0,6.08;8,3;8]image[0,4.85;1,1;gui_hb_bg.png]image[1,4.85;1,1;gui_hb_bg.png]image[2,4.85;1,1;gui_hb_bg.png]image[3,4.85;1,1;gui_hb_bg.png]image[4,4.85;1,1;gui_hb_bg.png]image[5,4.85;1,1;gui_hb_bg.png]image[6,4.85;1,1;gui_hb_bg.png]image[7,4.85;1,1;gui_hb_bg.png]"}, ["inventory"] = {["main"] = {"", "", "", "", "", "", "", "", "", "", "", "fachwerk:brick_1 23454", "", "default:dirt 99", "", "", "", "", "stairs:slab_junglewood 86", "default:pinewood 32", "default:dirt 3", "default:stick 4", "cottages:roof_straw 13", "", "fachwerk:brick_1 23447", "birch:sapling 10", "default:dirt 71", "default:junglewood", "", "default:dirt 99", "cottages:bench 2320", "default:dirt 99", "", "", "", ""}}}, ["param2"] = 3, ["y"] = 0, ["z"] = 17, ["name"] = "default:chest"}, {["x"] = 0, ["meta"] = {["fields"] = {["formspec"] = "size[8,8.5]bgcolor[#080808BB;true]background[5,5;1,1;gui_formbg.png;true]listcolors[#00000069;#5A5A5A;#141318;#30434C;#FFF]list[current_name;src;2.75,0.5;1,1;]list[current_name;fuel;2.75,2.5;1,1;]image[2.75,1.5;1,1;default_furnace_fire_bg.png]image[3.75,1.5;1,1;gui_furnace_arrow_bg.png^[transformR270]list[current_name;dst;4.75,0.96;2,2;]list[current_player;main;0,4.25;8,1;]list[current_player;main;0,5.5;8,3;8]image[0,4.25;1,1;gui_hb_bg.png]image[1,4.25;1,1;gui_hb_bg.png]image[2,4.25;1,1;gui_hb_bg.png]image[3,4.25;1,1;gui_hb_bg.png]image[4,4.25;1,1;gui_hb_bg.png]image[5,4.25;1,1;gui_hb_bg.png]image[6,4.25;1,1;gui_hb_bg.png]image[7,4.25;1,1;gui_hb_bg.png]", ["fuel_time"] = "0", ["fuel_totaltime"] = "0", ["src_time"] = "0", ["infotext"] = "Furnace inactive (Item: Not cookable; Fuel: 0%)"}, ["inventory"] = {["fuel"] = {"default:junglewood 10729"}, ["src"] = {"fachwerk:brick 11"}, ["dst"] = {"default:stone 99", "default:stone 99", "default:cobble", "default:stone 99"}}}, ["y"] = 0, ["z"] = 18, ["name"] = "default:furnace"}, {["x"] = 0, ["meta"] = {["fields"] = {}, ["inventory"] = {}}, ["param2"] = 12, ["y"] = 0, ["z"] = 19, ["name"] = "default:pinetree"}, {["x"] = 0, ["meta"] = {["fields"] = {}, ["inventory"] = {}}, ["y"] = 1, ["z"] = 12, ["name"] = "fachwerk:brick"}, {["x"] = 0, ["meta"] = {["fields"] = {}, ["inventory"] = {}}, ["param2"] = 3, ["y"] = 1, ["z"] = 13, ["name"] = "torches:wall"}, {["x"] = 0, ["meta"] = {["fields"] = {}, ["inventory"] = {}}, ["y"] = 1, ["z"] = 19, ["name"] = "fachwerk:brick_1"}, {["x"] = 0, ["meta"] = {["fields"] = {}, ["inventory"] = {}}, ["y"] = 2, ["z"] = 12, ["name"] = "fachwerk:brick"}, {["x"] = 0, ["meta"] = {["fields"] = {}, ["inventory"] = {}}, ["y"] = 2, ["z"] = 19, ["name"] = "fachwerk:brick_2"}, {["x"] = 0, ["meta"] = {["fields"] = {}, ["inventory"] = {}}, ["param2"] = 12, ["y"] = 3, ["param1"] = 153, ["z"] = 11, ["name"] = "stairs:stair_wood"}, {["x"] = 0, ["meta"] = {["fields"] = {}, ["inventory"] = {}}, ["y"] = 3, ["z"] = 12, ["name"] = "default:wood"}, {["x"] = 0, ["meta"] = {["fields"] = {}, ["inventory"] = {}}, ["y"] = 3, ["param1"] = 187, ["z"] = 13, ["name"] = "stairs:slab_wood"}, {["x"] = 0, ["meta"] = {["fields"] = {}, ["inventory"] = {}}, ["y"] = 3, ["param1"] = 170, ["z"] = 14, ["name"] = "stairs:slab_wood"}, {["x"] = 0, ["meta"] = {["fields"] = {}, ["inventory"] = {}}, ["y"] = 3, ["param1"] = 153, ["z"] = 15, ["name"] = "stairs:slab_wood"}, {["x"] = 0, ["meta"] = {["fields"] = {}, ["inventory"] = {}}, ["y"] = 3, ["param1"] = 136, ["z"] = 16, ["name"] = "stairs:slab_wood"}, {["x"] = 0, ["meta"] = {["fields"] = {}, ["inventory"] = {}}, ["y"] = 3, ["param1"] = 119, ["z"] = 17, ["name"] = "stairs:slab_wood"}, {["x"] = 0, ["meta"] = {["fields"] = {}, ["inventory"] = {}}, ["y"] = 3, ["param1"] = 102, ["z"] = 18, ["name"] = "stairs:slab_wood"}, {["x"] = 0, ["meta"] = {["fields"] = {}, ["inventory"] = {}}, ["y"] = 3, ["z"] = 19, ["name"] = "default:wood"}, {["x"] = 0, ["meta"] = {["fields"] = {}, ["inventory"] = {}}, ["param2"] = 4, ["y"] = 3, ["param1"] = 187, ["z"] = 20, ["name"] = "stairs:slab_wood"}, {["x"] = 0, ["meta"] = {["fields"] = {}, ["inventory"] = {}}, ["y"] = 4, ["z"] = 11, ["name"] = "fachwerk:brick"}, {["x"] = 0, ["meta"] = {["fields"] = {}, ["inventory"] = {}}, ["param2"] = 3, ["y"] = 4, ["param1"] = 170, ["z"] = 13, ["name"] = "default:ladder"}, {["x"] = 0, ["meta"] = {["fields"] = {}, ["inventory"] = {}}, ["y"] = 4, ["z"] = 20, ["name"] = "fachwerk:brick_1"}, {["x"] = 0, ["meta"] = {["fields"] = {}, ["inventory"] = {}}, ["y"] = 5, ["z"] = 11, ["name"] = "fachwerk:brick"}, {["x"] = 0, ["meta"] = {["fields"] = {}, ["inventory"] = {}}, ["param2"] = 3, ["y"] = 5, ["param1"] = 153, ["z"] = 13, ["name"] = "default:ladder"}, {["x"] = 0, ["meta"] = {["fields"] = {}, ["inventory"] = {}}, ["y"] = 5, ["z"] = 20, ["name"] = "fachwerk:brick_2"}, {["x"] = 0, ["meta"] = {["fields"] = {}, ["inventory"] = {}}, ["y"] = 6, ["z"] = 11, ["name"] = "fachwerk:brick"}, {["x"] = 0, ["meta"] = {["fields"] = {}, ["inventory"] = {}}, ["y"] = 6, ["param1"] = 119, ["z"] = 12, ["name"] = "stairs:slab_wood"}, {["x"] = 0, ["meta"] = {["fields"] = {}, ["inventory"] = {}}, ["param2"] = 3, ["y"] = 6, ["param1"] = 136, ["z"] = 13, ["name"] = "default:ladder"}, {["x"] = 0, ["meta"] = {["fields"] = {}, ["inventory"] = {}}, ["y"] = 6, ["param1"] = 119, ["z"] = 14, ["name"] = "stairs:slab_wood"}, {["x"] = 0, ["meta"] = {["fields"] = {}, ["inventory"] = {}}, ["y"] = 6, ["param1"] = 136, ["z"] = 15, ["name"] = "stairs:slab_wood"}, {["x"] = 0, ["meta"] = {["fields"] = {}, ["inventory"] = {}}, ["y"] = 6, ["param1"] = 153, ["z"] = 16, ["name"] = "stairs:slab_wood"}, {["x"] = 0, ["meta"] = {["fields"] = {}, ["inventory"] = {}}, ["y"] = 6, ["param1"] = 136, ["z"] = 17, ["name"] = "stairs:slab_wood"}, {["x"] = 0, ["meta"] = {["fields"] = {}, ["inventory"] = {}}, ["y"] = 6, ["param1"] = 119, ["z"] = 18, ["name"] = "stairs:slab_wood"}, {["x"] = 0, ["meta"] = {["fields"] = {}, ["inventory"] = {}}, ["y"] = 6, ["param1"] = 119, ["z"] = 19, ["name"] = "stairs:slab_wood"}, {["x"] = 0, ["meta"] = {["fields"] = {}, ["inventory"] = {}}, ["y"] = 6, ["z"] = 20, ["name"] = "fachwerk:brick"}, {["x"] = 0, ["meta"] = {["fields"] = {}, ["inventory"] = {}}, ["y"] = 6, ["z"] = 22, ["name"] = "farming:straw"}, {["x"] = 0, ["meta"] = {["fields"] = {}, ["inventory"] = {}}, ["y"] = 7, ["z"] = 5, ["name"] = "farming:straw"}, {["x"] = 0, ["meta"] = {["fields"] = {}, ["inventory"] = {}}, ["y"] = 7, ["z"] = 6, ["name"] = "farming:straw"}, {["x"] = 0, ["meta"] = {["fields"] = {}, ["inventory"] = {}}, ["y"] = 7, ["z"] = 7, ["name"] = "farming:straw"}, {["x"] = 0, ["meta"] = {["fields"] = {}, ["inventory"] = {}}, ["y"] = 7, ["z"] = 8, ["name"] = "farming:straw"}, {["x"] = 0, ["meta"] = {["fields"] = {}, ["inventory"] = {}}, ["y"] = 7, ["z"] = 9, ["name"] = "farming:straw"}, {["x"] = 0, ["meta"] = {["fields"] = {}, ["inventory"] = {}}, ["y"] = 7, ["z"] = 10, ["name"] = "farming:straw"}, {["x"] = 0, ["meta"] = {["fields"] = {}, ["inventory"] = {}}, ["y"] = 7, ["z"] = 11, ["name"] = "fachwerk:brick"}, {["x"] = 0, ["meta"] = {["fields"] = {}, ["inventory"] = {}}, ["param2"] = 3, ["y"] = 7, ["param1"] = 153, ["z"] = 15, ["name"] = "default:ladder"}, {["x"] = 0, ["meta"] = {["fields"] = {}, ["inventory"] = {}}, ["y"] = 7, ["z"] = 20, ["name"] = "fachwerk:brick"}, {["x"] = 0, ["meta"] = {["fields"] = {}, ["inventory"] = {}}, ["y"] = 7, ["z"] = 21, ["name"] = "farming:straw"}, {["x"] = 0, ["meta"] = {["fields"] = {}, ["inventory"] = {}}, ["y"] = 8, ["z"] = 11, ["name"] = "farming:straw"}, {["x"] = 0, ["meta"] = {["fields"] = {}, ["inventory"] = {}}, ["param2"] = 3, ["y"] = 8, ["param1"] = 170, ["z"] = 15, ["name"] = "default:ladder"}, {["x"] = 0, ["meta"] = {["fields"] = {}, ["inventory"] = {}}, ["y"] = 8, ["z"] = 20, ["name"] = "farming:straw"}, {["x"] = 0, ["meta"] = {["fields"] = {}, ["inventory"] = {}}, ["y"] = 9, ["z"] = 12, ["name"] = "farming:straw"}, {["x"] = 0, ["meta"] = {["fields"] = {}, ["inventory"] = {}}, ["param2"] = 1, ["y"] = 9, ["param1"] = 153, ["z"] = 13, ["name"] = "stairs:slab_wood"}, {["x"] = 0, ["meta"] = {["fields"] = {}, ["inventory"] = {}}, ["param2"] = 1, ["y"] = 9, ["param1"] = 170, ["z"] = 14, ["name"] = "stairs:slab_wood"}, {["x"] = 0, ["meta"] = {["fields"] = {}, ["inventory"] = {}}, ["param2"] = 3, ["y"] = 9, ["param1"] = 187, ["z"] = 15, ["name"] = "default:ladder"}, {["x"] = 0, ["meta"] = {["fields"] = {}, ["inventory"] = {}}, ["param2"] = 1, ["y"] = 9, ["param1"] = 204, ["z"] = 16, ["name"] = "stairs:slab_wood"}, {["x"] = 0, ["meta"] = {["fields"] = {}, ["inventory"] = {}}, ["param2"] = 1, ["y"] = 9, ["param1"] = 187, ["z"] = 17, ["name"] = "stairs:slab_wood"}, {["x"] = 0, ["meta"] = {["fields"] = {}, ["inventory"] = {}}, ["param2"] = 1, ["y"] = 9, ["param1"] = 170, ["z"] = 18, ["name"] = "stairs:slab_wood"}, {["x"] = 0, ["meta"] = {["fields"] = {}, ["inventory"] = {}}, ["y"] = 9, ["z"] = 19, ["name"] = "farming:straw"}, {["x"] = 0, ["meta"] = {["fields"] = {}, ["inventory"] = {}}, ["y"] = 10, ["z"] = 13, ["name"] = "farming:straw"}, {["x"] = 0, ["meta"] = {["fields"] = {}, ["inventory"] = {}}, ["param2"] = 3, ["y"] = 10, ["z"] = 16, ["name"] = "torches:wall"}, {["x"] = 0, ["meta"] = {["fields"] = {}, ["inventory"] = {}}, ["y"] = 10, ["z"] = 18, ["name"] = "farming:straw"}, {["x"] = 0, ["meta"] = {["fields"] = {}, ["inventory"] = {}}, ["y"] = 11, ["z"] = 14, ["name"] = "farming:straw"}, {["x"] = 0, ["meta"] = {["fields"] = {}, ["inventory"] = {}}, ["y"] = 11, ["z"] = 17, ["name"] = "farming:straw"}, {["x"] = 0, ["meta"] = {["fields"] = {}, ["inventory"] = {}}, ["y"] = 12, ["z"] = 15, ["name"] = "farming:straw"}, {["x"] = 0, ["meta"] = {["fields"] = {}, ["inventory"] = {}}, ["y"] = 12, ["z"] = 16, ["name"] = "farming:straw"}, {["x"] = 1, ["meta"] = {["fields"] = {}, ["inventory"] = {}}, ["param2"] = 18, ["y"] = 0, ["z"] = 12, ["name"] = "default:pinetree"}, {["x"] = 1, ["meta"] = {["fields"] = {["infotext"] = "Trash Can", ["formspec"] = "size[8,9]button[0,0;2,1;empty;Empty Trash]list[current_name;main;3,1;2,3;]list[current_player;main;0,5;8,4;]"}, ["inventory"] = {["main"] = {"", "", "", "", "", "", "", "", "", "", "", "", "", "", "", "", "", "", "", "", "", "", "", "", "", "", "", "", "", "", "", ""}}}, ["y"] = 0, ["param1"] = 119, ["z"] = 18, ["name"] = "trash_can:trash_can_wooden"}, {["x"] = 1, ["meta"] = {["fields"] = {}, ["inventory"] = {}}, ["param2"] = 12, ["y"] = 0, ["z"] = 19, ["name"] = "default:pinetree"}, {["x"] = 1, ["meta"] = {["fields"] = {}, ["inventory"] = {}}, ["y"] = 1, ["param1"] = 187, ["z"] = 12, ["name"] = "default:glass"}, {["x"] = 1, ["meta"] = {["fields"] = {}, ["inventory"] = {}}, ["y"] = 1, ["param1"] = 153, ["z"] = 19, ["name"] = "default:glass"}, {["x"] = 1, ["meta"] = {["fields"] = {}, ["inventory"] = {}}, ["y"] = 2, ["z"] = 12, ["name"] = "fachwerk:brick_2"}, {["x"] = 1, ["meta"] = {["fields"] = {}, ["inventory"] = {}}, ["y"] = 2, ["z"] = 19, ["name"] = "fachwerk:brick"}, {["x"] = 1, ["meta"] = {["fields"] = {}, ["inventory"] = {}}, ["param2"] = 8, ["y"] = 3, ["param1"] = 170, ["z"] = 11, ["name"] = "stairs:slab_wood"}, {["x"] = 1, ["meta"] = {["fields"] = {}, ["inventory"] = {}}, ["y"] = 3, ["z"] = 12, ["name"] = "default:wood"}, {["x"] = 1, ["meta"] = {["fields"] = {}, ["inventory"] = {}}, ["y"] = 3, ["param1"] = 170, ["z"] = 13, ["name"] = "stairs:slab_wood"}, {["x"] = 1, ["meta"] = {["fields"] = {}, ["inventory"] = {}}, ["y"] = 3, ["param1"] = 153, ["z"] = 14, ["name"] = "stairs:slab_wood"}, {["x"] = 1, ["meta"] = {["fields"] = {}, ["inventory"] = {}}, ["y"] = 3, ["param1"] = 136, ["z"] = 15, ["name"] = "stairs:slab_wood"}, {["x"] = 1, ["meta"] = {["fields"] = {}, ["inventory"] = {}}, ["y"] = 3, ["param1"] = 119, ["z"] = 16, ["name"] = "stairs:slab_wood"}, {["x"] = 1, ["meta"] = {["fields"] = {}, ["inventory"] = {}}, ["y"] = 3, ["param1"] = 102, ["z"] = 17, ["name"] = "stairs:slab_wood"}, {["x"] = 1, ["meta"] = {["fields"] = {}, ["inventory"] = {}}, ["y"] = 3, ["param1"] = 102, ["z"] = 18, ["name"] = "stairs:slab_wood"}, {["x"] = 1, ["meta"] = {["fields"] = {}, ["inventory"] = {}}, ["y"] = 3, ["z"] = 19, ["name"] = "default:wood"}, {["x"] = 1, ["meta"] = {["fields"] = {}, ["inventory"] = {}}, ["param2"] = 4, ["y"] = 3, ["param1"] = 170, ["z"] = 20, ["name"] = "stairs:slab_wood"}, {["x"] = 1, ["meta"] = {["fields"] = {}, ["inventory"] = {}}, ["y"] = 4, ["z"] = 11, ["name"] = "fachwerk:brick"}, {["x"] = 1, ["meta"] = {["fields"] = {}, ["inventory"] = {}}, ["y"] = 4, ["z"] = 20, ["name"] = "fachwerk:brick"}, {["x"] = 1, ["meta"] = {["fields"] = {}, ["inventory"] = {}}, ["y"] = 5, ["param1"] = 103, ["z"] = 11, ["name"] = "default:glass"}, {["x"] = 1, ["meta"] = {["fields"] = {}, ["inventory"] = {}}, ["y"] = 5, ["param1"] = 170, ["z"] = 20, ["name"] = "default:glass"}, {["x"] = 1, ["meta"] = {["fields"] = {}, ["inventory"] = {}}, ["y"] = 6, ["z"] = 6, ["name"] = "farming:straw"}, {["x"] = 1, ["meta"] = {["fields"] = {}, ["inventory"] = {}}, ["y"] = 6, ["z"] = 7, ["name"] = "farming:straw"}, {["x"] = 1, ["meta"] = {["fields"] = {}, ["inventory"] = {}}, ["y"] = 6, ["z"] = 8, ["name"] = "farming:straw"}, {["x"] = 1, ["meta"] = {["fields"] = {}, ["inventory"] = {}}, ["y"] = 6, ["z"] = 9, ["name"] = "farming:straw"}, {["x"] = 1, ["meta"] = {["fields"] = {}, ["inventory"] = {}}, ["y"] = 6, ["z"] = 11, ["name"] = "fachwerk:brick"}, {["x"] = 1, ["meta"] = {["fields"] = {}, ["inventory"] = {}}, ["y"] = 6, ["param1"] = 102, ["z"] = 12, ["name"] = "stairs:slab_wood"}, {["x"] = 1, ["meta"] = {["fields"] = {}, ["inventory"] = {}}, ["y"] = 6, ["param1"] = 119, ["z"] = 13, ["name"] = "stairs:slab_wood"}, {["x"] = 1, ["meta"] = {["fields"] = {}, ["inventory"] = {}}, ["y"] = 6, ["param1"] = 102, ["z"] = 14, ["name"] = "stairs:slab_wood"}, {["x"] = 1, ["meta"] = {["fields"] = {}, ["inventory"] = {}}, ["y"] = 6, ["param1"] = 119, ["z"] = 15, ["name"] = "stairs:slab_wood"}, {["x"] = 1, ["meta"] = {["fields"] = {}, ["inventory"] = {}}, ["y"] = 6, ["param1"] = 136, ["z"] = 16, ["name"] = "stairs:slab_wood"}, {["x"] = 1, ["meta"] = {["fields"] = {}, ["inventory"] = {}}, ["y"] = 6, ["param1"] = 119, ["z"] = 17, ["name"] = "stairs:slab_wood"}, {["x"] = 1, ["meta"] = {["fields"] = {}, ["inventory"] = {}}, ["y"] = 6, ["param1"] = 119, ["z"] = 18, ["name"] = "stairs:slab_wood"}, {["x"] = 1, ["meta"] = {["fields"] = {}, ["inventory"] = {}}, ["y"] = 6, ["param1"] = 136, ["z"] = 19, ["name"] = "stairs:slab_wood"}, {["x"] = 1, ["meta"] = {["fields"] = {}, ["inventory"] = {}}, ["y"] = 6, ["z"] = 20, ["name"] = "fachwerk:brick"}, {["x"] = 1, ["meta"] = {["fields"] = {}, ["inventory"] = {}}, ["y"] = 6, ["z"] = 22, ["name"] = "farming:straw"}, {["x"] = 1, ["meta"] = {["fields"] = {}, ["inventory"] = {}}, ["y"] = 7, ["z"] = 10, ["name"] = "farming:straw"}, {["x"] = 1, ["meta"] = {["fields"] = {}, ["inventory"] = {}}, ["y"] = 7, ["z"] = 11, ["name"] = "fachwerk:brick"}, {["x"] = 1, ["meta"] = {["fields"] = {}, ["inventory"] = {}}, ["y"] = 7, ["z"] = 20, ["name"] = "fachwerk:brick"}, {["x"] = 1, ["meta"] = {["fields"] = {}, ["inventory"] = {}}, ["y"] = 7, ["z"] = 21, ["name"] = "farming:straw"}, {["x"] = 1, ["meta"] = {["fields"] = {}, ["inventory"] = {}}, ["y"] = 8, ["z"] = 11, ["name"] = "farming:straw"}, {["x"] = 1, ["meta"] = {["fields"] = {}, ["inventory"] = {}}, ["y"] = 8, ["z"] = 20, ["name"] = "farming:straw"}, {["x"] = 1, ["meta"] = {["fields"] = {}, ["inventory"] = {}}, ["y"] = 9, ["z"] = 12, ["name"] = "farming:straw"}, {["x"] = 1, ["meta"] = {["fields"] = {}, ["inventory"] = {}}, ["param2"] = 1, ["y"] = 9, ["param1"] = 136, ["z"] = 13, ["name"] = "stairs:slab_wood"}, {["x"] = 1, ["meta"] = {["fields"] = {}, ["inventory"] = {}}, ["param2"] = 1, ["y"] = 9, ["param1"] = 153, ["z"] = 14, ["name"] = "stairs:slab_wood"}, {["x"] = 1, ["meta"] = {["fields"] = {}, ["inventory"] = {}}, ["param2"] = 1, ["y"] = 9, ["param1"] = 170, ["z"] = 15, ["name"] = "stairs:slab_wood"}, {["x"] = 1, ["meta"] = {["fields"] = {}, ["inventory"] = {}}, ["param2"] = 1, ["y"] = 9, ["param1"] = 187, ["z"] = 16, ["name"] = "stairs:slab_wood"}, {["x"] = 1, ["meta"] = {["fields"] = {}, ["inventory"] = {}}, ["param2"] = 1, ["y"] = 9, ["param1"] = 170, ["z"] = 17, ["name"] = "stairs:slab_wood"}, {["x"] = 1, ["meta"] = {["fields"] = {}, ["inventory"] = {}}, ["param2"] = 1, ["y"] = 9, ["param1"] = 153, ["z"] = 18, ["name"] = "stairs:slab_wood"}, {["x"] = 1, ["meta"] = {["fields"] = {}, ["inventory"] = {}}, ["y"] = 9, ["z"] = 19, ["name"] = "farming:straw"}, {["x"] = 1, ["meta"] = {["fields"] = {}, ["inventory"] = {}}, ["y"] = 10, ["z"] = 13, ["name"] = "farming:straw"}, {["x"] = 1, ["meta"] = {["fields"] = {}, ["inventory"] = {}}, ["y"] = 10, ["z"] = 18, ["name"] = "farming:straw"}, {["x"] = 1, ["meta"] = {["fields"] = {}, ["inventory"] = {}}, ["y"] = 11, ["z"] = 14, ["name"] = "farming:straw"}, {["x"] = 1, ["meta"] = {["fields"] = {}, ["inventory"] = {}}, ["y"] = 11, ["z"] = 17, ["name"] = "farming:straw"}, {["x"] = 1, ["meta"] = {["fields"] = {}, ["inventory"] = {}}, ["y"] = 12, ["z"] = 15, ["name"] = "farming:straw"}, {["x"] = 1, ["meta"] = {["fields"] = {}, ["inventory"] = {}}, ["y"] = 12, ["z"] = 16, ["name"] = "farming:straw"}, {["x"] = 2, ["meta"] = {["fields"] = {}, ["inventory"] = {}}, ["param2"] = 18, ["y"] = 0, ["z"] = 12, ["name"] = "default:pinetree"}, {["x"] = 2, ["meta"] = {["fields"] = {}, ["inventory"] = {}}, ["y"] = 0, ["param1"] = 136, ["z"] = 18, ["name"] = "crafting:workbench"}, {["x"] = 2, ["meta"] = {["fields"] = {}, ["inventory"] = {}}, ["param2"] = 12, ["y"] = 0, ["z"] = 19, ["name"] = "default:pinetree"}, {["x"] = 2, ["meta"] = {["fields"] = {}, ["inventory"] = {}}, ["y"] = 1, ["z"] = 12, ["name"] = "fachwerk:brick"}, {["x"] = 2, ["meta"] = {["fields"] = {}, ["inventory"] = {}}, ["param2"] = 5, ["y"] = 1, ["z"] = 13, ["name"] = "torches:wall"}, {["x"] = 2, ["meta"] = {["fields"] = {["formspec"] = "size[14,10;]list[current_name;main;0,0;14,5;1]label[0,5;--== Learn to Craft ==--]label[0,5.4;Drag any item to the Output box to see the]label[0,5.8;craft. Save your favorite items in Bookmarks.]field[6,5.4;2,1;craft_guide_search_box;;]button[7.5,5.1;1.2,1;craft_guide_search_button;Search]label[9,5.2;page 1 of 1]button[11,5;1.5,1;craft_guide_prev;<<]button[12.5,5;1.5,1;craft_guide_next;>>]label[0,6.5;Output]list[current_name;output;0,7;1,1;]label[2,6.5;Inventory Craft]list[current_name;build;2,7;3,3;]label[6,6.5;Cook]list[current_name;cook;6,7;1,1;]label[6,8.5;Fuel]list[current_name;fuel;6,9;1,1;]label[8,6.5;Bookmarks]list[current_name;bookmark;8,7;6,3;]label[12,6.1;Bin ->]list[current_name;bin;13,6;1,1;]"}, ["inventory"] = {["bin"] = {""}, ["build"] = {"", "", "", "", "", "", "", "", ""}, ["main"] = {"craft_guide:lcd_pc", "craft_guide:sign_wall"}, ["bookmark"] = {"", "", "", "", "", "", "", "", "", "", "", "", "", "", "", "", "", ""}, ["fuel"] = {""}, ["output"] = {""}, ["cook"] = {""}}}, ["param2"] = 4, ["y"] = 1, ["param1"] = 153, ["z"] = 18, ["name"] = "craft_guide:sign_wall"}, {["x"] = 2, ["meta"] = {["fields"] = {}, ["inventory"] = {}}, ["y"] = 1, ["z"] = 19, ["name"] = "fachwerk:brick"}, {["x"] = 2, ["meta"] = {["fields"] = {}, ["inventory"] = {}}, ["y"] = 2, ["z"] = 12, ["name"] = "fachwerk:brick"}, {["x"] = 2, ["meta"] = {["fields"] = {["formspec"] = "size[14,10;]list[current_name;main;0,0;14,5;1]label[0,5;--== Learn to Craft ==--]label[0,5.4;Drag any item to the Output box to see the]label[0,5.8;craft. Save your favorite items in Bookmarks.]field[6,5.4;2,1;craft_guide_search_box;;]button[7.5,5.1;1.2,1;craft_guide_search_button;Search]label[9,5.2;page 1 of 1]button[11,5;1.5,1;craft_guide_prev;<<]button[12.5,5;1.5,1;craft_guide_next;>>]label[0,6.5;Output]list[current_name;output;0,7;1,1;]label[2,6.5;Inventory Craft]list[current_name;build;2,7;3,3;]label[6,6.5;Cook]list[current_name;cook;6,7;1,1;]label[6,8.5;Fuel]list[current_name;fuel;6,9;1,1;]label[8,6.5;Bookmarks]list[current_name;bookmark;8,7;6,3;]label[12,6.1;Bin ->]list[current_name;bin;13,6;1,1;]"}, ["inventory"] = {["bin"] = {""}, ["build"] = {"", "", "", "", "", "", "", "", ""}, ["main"] = {"craft_guide:lcd_pc", "craft_guide:sign_wall"}, ["bookmark"] = {"", "", "", "", "", "", "", "", "", "", "", "", "", "", "", "", "", ""}, ["fuel"] = {""}, ["output"] = {""}, ["cook"] = {""}}}, ["param2"] = 4, ["y"] = 2, ["param1"] = 136, ["z"] = 18, ["name"] = "craft_guide:sign_wall"}, {["x"] = 2, ["meta"] = {["fields"] = {}, ["inventory"] = {}}, ["y"] = 2, ["z"] = 19, ["name"] = "fachwerk:brick"}, {["x"] = 2, ["meta"] = {["fields"] = {}, ["inventory"] = {}}, ["param2"] = 8, ["y"] = 3, ["param1"] = 187, ["z"] = 11, ["name"] = "stairs:slab_wood"}, {["x"] = 2, ["meta"] = {["fields"] = {}, ["inventory"] = {}}, ["y"] = 3, ["z"] = 12, ["name"] = "default:wood"}, {["x"] = 2, ["meta"] = {["fields"] = {}, ["inventory"] = {}}, ["y"] = 3, ["param1"] = 187, ["z"] = 13, ["name"] = "stairs:slab_wood"}, {["x"] = 2, ["meta"] = {["fields"] = {}, ["inventory"] = {}}, ["y"] = 3, ["param1"] = 170, ["z"] = 14, ["name"] = "stairs:slab_wood"}, {["x"] = 2, ["meta"] = {["fields"] = {}, ["inventory"] = {}}, ["y"] = 3, ["param1"] = 153, ["z"] = 15, ["name"] = "stairs:slab_wood"}, {["x"] = 2, ["meta"] = {["fields"] = {}, ["inventory"] = {}}, ["y"] = 3, ["param1"] = 136, ["z"] = 16, ["name"] = "stairs:slab_wood"}, {["x"] = 2, ["meta"] = {["fields"] = {}, ["inventory"] = {}}, ["y"] = 3, ["param1"] = 119, ["z"] = 17, ["name"] = "stairs:slab_wood"}, {["x"] = 2, ["meta"] = {["fields"] = {}, ["inventory"] = {}}, ["y"] = 3, ["param1"] = 119, ["z"] = 18, ["name"] = "stairs:slab_wood"}, {["x"] = 2, ["meta"] = {["fields"] = {}, ["inventory"] = {}}, ["y"] = 3, ["z"] = 19, ["name"] = "default:wood"}, {["x"] = 2, ["meta"] = {["fields"] = {}, ["inventory"] = {}}, ["param2"] = 4, ["y"] = 3, ["param1"] = 187, ["z"] = 20, ["name"] = "stairs:slab_wood"}, {["x"] = 2, ["meta"] = {["fields"] = {}, ["inventory"] = {}}, ["y"] = 4, ["z"] = 11, ["name"] = "fachwerk:brick_1"}, {["x"] = 2, ["meta"] = {["fields"] = {}, ["inventory"] = {}}, ["y"] = 4, ["z"] = 20, ["name"] = "fachwerk:brick"}, {["x"] = 2, ["meta"] = {["fields"] = {}, ["inventory"] = {}}, ["y"] = 5, ["z"] = 11, ["name"] = "fachwerk:brick_2"}, {["x"] = 2, ["meta"] = {["fields"] = {}, ["inventory"] = {}}, ["y"] = 5, ["z"] = 20, ["name"] = "fachwerk:brick"}, {["x"] = 2, ["meta"] = {["fields"] = {}, ["inventory"] = {}}, ["y"] = 6, ["z"] = 9, ["name"] = "farming:straw"}, {["x"] = 2, ["meta"] = {["fields"] = {}, ["inventory"] = {}}, ["y"] = 6, ["z"] = 11, ["name"] = "fachwerk:brick"}, {["x"] = 2, ["meta"] = {["fields"] = {}, ["inventory"] = {}}, ["y"] = 6, ["param1"] = 119, ["z"] = 12, ["name"] = "stairs:slab_wood"}, {["x"] = 2, ["meta"] = {["fields"] = {}, ["inventory"] = {}}, ["y"] = 6, ["param1"] = 136, ["z"] = 13, ["name"] = "stairs:slab_wood"}, {["x"] = 2, ["meta"] = {["fields"] = {}, ["inventory"] = {}}, ["y"] = 6, ["param1"] = 119, ["z"] = 14, ["name"] = "stairs:slab_wood"}, {["x"] = 2, ["meta"] = {["fields"] = {}, ["inventory"] = {}}, ["y"] = 6, ["param1"] = 102, ["z"] = 15, ["name"] = "stairs:slab_wood"}, {["x"] = 2, ["meta"] = {["fields"] = {}, ["inventory"] = {}}, ["y"] = 6, ["param1"] = 119, ["z"] = 16, ["name"] = "stairs:slab_wood"}, {["x"] = 2, ["meta"] = {["fields"] = {}, ["inventory"] = {}}, ["y"] = 6, ["param1"] = 102, ["z"] = 17, ["name"] = "stairs:slab_wood"}, {["x"] = 2, ["meta"] = {["fields"] = {}, ["inventory"] = {}}, ["y"] = 6, ["param1"] = 103, ["z"] = 18, ["name"] = "stairs:slab_wood"}, {["x"] = 2, ["meta"] = {["fields"] = {}, ["inventory"] = {}}, ["y"] = 6, ["param1"] = 119, ["z"] = 19, ["name"] = "stairs:slab_wood"}, {["x"] = 2, ["meta"] = {["fields"] = {}, ["inventory"] = {}}, ["y"] = 6, ["z"] = 20, ["name"] = "fachwerk:brick"}, {["x"] = 2, ["meta"] = {["fields"] = {}, ["inventory"] = {}}, ["y"] = 6, ["z"] = 22, ["name"] = "farming:straw"}, {["x"] = 2, ["meta"] = {["fields"] = {}, ["inventory"] = {}}, ["y"] = 7, ["z"] = 10, ["name"] = "farming:straw"}, {["x"] = 2, ["meta"] = {["fields"] = {}, ["inventory"] = {}}, ["y"] = 7, ["z"] = 11, ["name"] = "fachwerk:brick"}, {["x"] = 2, ["meta"] = {["fields"] = {}, ["inventory"] = {}}, ["y"] = 7, ["z"] = 20, ["name"] = "fachwerk:brick"}, {["x"] = 2, ["meta"] = {["fields"] = {}, ["inventory"] = {}}, ["y"] = 7, ["z"] = 21, ["name"] = "farming:straw"}, {["x"] = 2, ["meta"] = {["fields"] = {}, ["inventory"] = {}}, ["y"] = 8, ["z"] = 11, ["name"] = "farming:straw"}, {["x"] = 2, ["meta"] = {["fields"] = {}, ["inventory"] = {}}, ["y"] = 8, ["z"] = 20, ["name"] = "farming:straw"}, {["x"] = 2, ["meta"] = {["fields"] = {}, ["inventory"] = {}}, ["y"] = 9, ["z"] = 12, ["name"] = "farming:straw"}, {["x"] = 2, ["meta"] = {["fields"] = {}, ["inventory"] = {}}, ["param2"] = 1, ["y"] = 9, ["param1"] = 119, ["z"] = 13, ["name"] = "stairs:slab_wood"}, {["x"] = 2, ["meta"] = {["fields"] = {}, ["inventory"] = {}}, ["param2"] = 1, ["y"] = 9, ["param1"] = 136, ["z"] = 14, ["name"] = "stairs:slab_wood"}, {["x"] = 2, ["meta"] = {["fields"] = {}, ["inventory"] = {}}, ["param2"] = 1, ["y"] = 9, ["param1"] = 153, ["z"] = 15, ["name"] = "stairs:slab_wood"}, {["x"] = 2, ["meta"] = {["fields"] = {}, ["inventory"] = {}}, ["param2"] = 1, ["y"] = 9, ["param1"] = 170, ["z"] = 16, ["name"] = "stairs:slab_wood"}, {["x"] = 2, ["meta"] = {["fields"] = {}, ["inventory"] = {}}, ["param2"] = 1, ["y"] = 9, ["param1"] = 153, ["z"] = 17, ["name"] = "stairs:slab_wood"}, {["x"] = 2, ["meta"] = {["fields"] = {}, ["inventory"] = {}}, ["param2"] = 1, ["y"] = 9, ["param1"] = 138, ["z"] = 18, ["name"] = "stairs:slab_wood"}, {["x"] = 2, ["meta"] = {["fields"] = {}, ["inventory"] = {}}, ["y"] = 9, ["z"] = 19, ["name"] = "farming:straw"}, {["x"] = 2, ["meta"] = {["fields"] = {}, ["inventory"] = {}}, ["y"] = 10, ["z"] = 13, ["name"] = "farming:straw"}, {["x"] = 2, ["meta"] = {["fields"] = {}, ["inventory"] = {}}, ["y"] = 10, ["z"] = 18, ["name"] = "farming:straw"}, {["x"] = 2, ["meta"] = {["fields"] = {}, ["inventory"] = {}}, ["param2"] = 1, ["y"] = 10, ["param1"] = 76, ["z"] = 19, ["name"] = "cottages:roof_connector_straw"}, {["x"] = 2, ["meta"] = {["fields"] = {}, ["inventory"] = {}}, ["param2"] = 1, ["y"] = 10, ["param1"] = 60, ["z"] = 20, ["name"] = "cottages:roof_straw"}, {["x"] = 2, ["meta"] = {["fields"] = {}, ["inventory"] = {}}, ["y"] = 11, ["z"] = 14, ["name"] = "farming:straw"}, {["x"] = 2, ["meta"] = {["fields"] = {}, ["inventory"] = {}}, ["y"] = 11, ["z"] = 17, ["name"] = "farming:straw"}, {["x"] = 2, ["meta"] = {["fields"] = {}, ["inventory"] = {}}, ["y"] = 12, ["z"] = 15, ["name"] = "farming:straw"}, {["x"] = 2, ["meta"] = {["fields"] = {}, ["inventory"] = {}}, ["y"] = 12, ["z"] = 16, ["name"] = "farming:straw"}, {["x"] = 3, ["meta"] = {["fields"] = {}, ["inventory"] = {}}, ["param2"] = 18, ["y"] = 0, ["z"] = 12, ["name"] = "default:pinetree"}, {["x"] = 3, ["meta"] = {["fields"] = {}, ["inventory"] = {}}, ["param2"] = 12, ["y"] = 0, ["z"] = 19, ["name"] = "default:pinetree"}, {["x"] = 3, ["meta"] = {["fields"] = {}, ["inventory"] = {}}, ["y"] = 1, ["z"] = 12, ["name"] = "fachwerk:brick"}, {["x"] = 3, ["meta"] = {["fields"] = {}, ["inventory"] = {}}, ["y"] = 1, ["param1"] = 187, ["z"] = 19, ["name"] = "default:glass"}, {["x"] = 3, ["meta"] = {["fields"] = {}, ["inventory"] = {}}, ["param2"] = 4, ["y"] = 2, ["z"] = 11, ["name"] = "torches:wall"}, {["x"] = 3, ["meta"] = {["fields"] = {}, ["inventory"] = {}}, ["y"] = 2, ["z"] = 12, ["name"] = "fachwerk:brick"}, {["x"] = 3, ["meta"] = {["fields"] = {}, ["inventory"] = {}}, ["y"] = 2, ["z"] = 19, ["name"] = "fachwerk:brick_2"}, {["x"] = 3, ["meta"] = {["fields"] = {}, ["inventory"] = {}}, ["param2"] = 5, ["y"] = 2, ["z"] = 20, ["name"] = "torches:wall"}, {["x"] = 3, ["meta"] = {["fields"] = {}, ["inventory"] = {}}, ["param2"] = 8, ["y"] = 3, ["param1"] = 204, ["z"] = 11, ["name"] = "stairs:slab_wood"}, {["x"] = 3, ["meta"] = {["fields"] = {}, ["inventory"] = {}}, ["y"] = 3, ["z"] = 12, ["name"] = "default:wood"}, {["x"] = 3, ["meta"] = {["fields"] = {}, ["inventory"] = {}}, ["y"] = 3, ["param1"] = 170, ["z"] = 13, ["name"] = "stairs:slab_wood"}, {["x"] = 3, ["meta"] = {["fields"] = {}, ["inventory"] = {}}, ["y"] = 3, ["param1"] = 153, ["z"] = 14, ["name"] = "stairs:slab_wood"}, {["x"] = 3, ["meta"] = {["fields"] = {}, ["inventory"] = {}}, ["y"] = 3, ["param1"] = 136, ["z"] = 15, ["name"] = "stairs:slab_wood"}, {["x"] = 3, ["meta"] = {["fields"] = {}, ["inventory"] = {}}, ["y"] = 3, ["param1"] = 119, ["z"] = 16, ["name"] = "stairs:slab_wood"}, {["x"] = 3, ["meta"] = {["fields"] = {}, ["inventory"] = {}}, ["y"] = 3, ["param1"] = 119, ["z"] = 17, ["name"] = "stairs:slab_wood"}, {["x"] = 3, ["meta"] = {["fields"] = {}, ["inventory"] = {}}, ["y"] = 3, ["param1"] = 136, ["z"] = 18, ["name"] = "stairs:slab_wood"}, {["x"] = 3, ["meta"] = {["fields"] = {}, ["inventory"] = {}}, ["y"] = 3, ["z"] = 19, ["name"] = "default:wood"}, {["x"] = 3, ["meta"] = {["fields"] = {}, ["inventory"] = {}}, ["param2"] = 4, ["y"] = 3, ["param1"] = 204, ["z"] = 20, ["name"] = "stairs:slab_wood"}, {["x"] = 3, ["meta"] = {["fields"] = {}, ["inventory"] = {}}, ["y"] = 4, ["z"] = 11, ["name"] = "fachwerk:brick"}, {["x"] = 3, ["meta"] = {["fields"] = {}, ["inventory"] = {}}, ["y"] = 4, ["z"] = 20, ["name"] = "fachwerk:brick"}, {["x"] = 3, ["meta"] = {["fields"] = {}, ["inventory"] = {}}, ["y"] = 5, ["z"] = 11, ["name"] = "fachwerk:brick"}, {["x"] = 3, ["meta"] = {["fields"] = {}, ["inventory"] = {}}, ["y"] = 5, ["z"] = 20, ["name"] = "fachwerk:brick"}, {["x"] = 3, ["meta"] = {["fields"] = {}, ["inventory"] = {}}, ["param2"] = 5, ["y"] = 5, ["z"] = 21, ["name"] = "torches:wall"}, {["x"] = 3, ["meta"] = {["fields"] = {}, ["inventory"] = {}}, ["y"] = 6, ["z"] = 9, ["name"] = "farming:straw"}, {["x"] = 3, ["meta"] = {["fields"] = {}, ["inventory"] = {}}, ["y"] = 6, ["z"] = 11, ["name"] = "fachwerk:brick"}, {["x"] = 3, ["meta"] = {["fields"] = {}, ["inventory"] = {}}, ["y"] = 6, ["param1"] = 103, ["z"] = 12, ["name"] = "stairs:slab_wood"}, {["x"] = 3, ["meta"] = {["fields"] = {}, ["inventory"] = {}}, ["y"] = 6, ["param1"] = 119, ["z"] = 13, ["name"] = "stairs:slab_wood"}, {["x"] = 3, ["meta"] = {["fields"] = {}, ["inventory"] = {}}, ["y"] = 6, ["param1"] = 102, ["z"] = 14, ["name"] = "stairs:slab_wood"}, {["x"] = 3, ["meta"] = {["fields"] = {}, ["inventory"] = {}}, ["y"] = 6, ["param1"] = 85, ["z"] = 15, ["name"] = "stairs:slab_wood"}, {["x"] = 3, ["meta"] = {["fields"] = {}, ["inventory"] = {}}, ["y"] = 6, ["param1"] = 102, ["z"] = 16, ["name"] = "stairs:slab_wood"}, {["x"] = 3, ["meta"] = {["fields"] = {}, ["inventory"] = {}}, ["y"] = 6, ["param1"] = 87, ["z"] = 17, ["name"] = "stairs:slab_wood"}, {["x"] = 3, ["meta"] = {["fields"] = {}, ["inventory"] = {}}, ["y"] = 6, ["param1"] = 88, ["z"] = 18, ["name"] = "stairs:slab_wood"}, {["x"] = 3, ["meta"] = {["fields"] = {}, ["inventory"] = {}}, ["y"] = 6, ["param1"] = 103, ["z"] = 19, ["name"] = "stairs:slab_wood"}, {["x"] = 3, ["meta"] = {["fields"] = {}, ["inventory"] = {}}, ["y"] = 6, ["z"] = 20, ["name"] = "fachwerk:brick"}, {["x"] = 3, ["meta"] = {["fields"] = {}, ["inventory"] = {}}, ["y"] = 6, ["z"] = 22, ["name"] = "farming:straw"}, {["x"] = 3, ["meta"] = {["fields"] = {}, ["inventory"] = {}}, ["y"] = 7, ["z"] = 10, ["name"] = "farming:straw"}, {["x"] = 3, ["meta"] = {["fields"] = {}, ["inventory"] = {}}, ["y"] = 7, ["z"] = 11, ["name"] = "fachwerk:brick"}, {["x"] = 3, ["meta"] = {["fields"] = {}, ["inventory"] = {}}, ["y"] = 7, ["z"] = 20, ["name"] = "fachwerk:brick"}, {["x"] = 3, ["meta"] = {["fields"] = {}, ["inventory"] = {}}, ["y"] = 7, ["z"] = 21, ["name"] = "farming:straw"}, {["x"] = 3, ["meta"] = {["fields"] = {}, ["inventory"] = {}}, ["y"] = 8, ["z"] = 11, ["name"] = "farming:straw"}, {["x"] = 3, ["meta"] = {["fields"] = {}, ["inventory"] = {}}, ["y"] = 8, ["z"] = 20, ["name"] = "farming:straw"}, {["x"] = 3, ["meta"] = {["fields"] = {}, ["inventory"] = {}}, ["y"] = 9, ["z"] = 12, ["name"] = "farming:straw"}, {["x"] = 3, ["meta"] = {["fields"] = {}, ["inventory"] = {}}, ["param2"] = 1, ["y"] = 9, ["param1"] = 102, ["z"] = 13, ["name"] = "stairs:slab_wood"}, {["x"] = 3, ["meta"] = {["fields"] = {}, ["inventory"] = {}}, ["param2"] = 1, ["y"] = 9, ["param1"] = 119, ["z"] = 14, ["name"] = "stairs:slab_wood"}, {["x"] = 3, ["meta"] = {["fields"] = {}, ["inventory"] = {}}, ["param2"] = 1, ["y"] = 9, ["param1"] = 136, ["z"] = 15, ["name"] = "stairs:slab_wood"}, {["x"] = 3, ["meta"] = {["fields"] = {}, ["inventory"] = {}}, ["param2"] = 1, ["y"] = 9, ["param1"] = 153, ["z"] = 16, ["name"] = "stairs:slab_wood"}, {["x"] = 3, ["meta"] = {["fields"] = {}, ["inventory"] = {}}, ["param2"] = 1, ["y"] = 9, ["param1"] = 138, ["z"] = 17, ["name"] = "stairs:slab_wood"}, {["x"] = 3, ["meta"] = {["fields"] = {}, ["inventory"] = {}}, ["param2"] = 1, ["y"] = 9, ["param1"] = 123, ["z"] = 18, ["name"] = "stairs:slab_wood"}, {["x"] = 3, ["meta"] = {["fields"] = {}, ["inventory"] = {}}, ["y"] = 9, ["z"] = 19, ["name"] = "farming:straw"}, {["x"] = 3, ["meta"] = {["fields"] = {}, ["inventory"] = {}}, ["y"] = 10, ["z"] = 13, ["name"] = "farming:straw"}, {["x"] = 3, ["meta"] = {["fields"] = {}, ["inventory"] = {}}, ["param2"] = 8, ["y"] = 10, ["param1"] = 140, ["z"] = 18, ["name"] = "cottages:roof_flat_straw"}, {["x"] = 3, ["meta"] = {["fields"] = {}, ["inventory"] = {}}, ["y"] = 10, ["z"] = 19, ["name"] = "fachwerk:brick"}, {["x"] = 3, ["meta"] = {["fields"] = {}, ["inventory"] = {}}, ["y"] = 11, ["z"] = 14, ["name"] = "farming:straw"}, {["x"] = 3, ["meta"] = {["fields"] = {}, ["inventory"] = {}}, ["y"] = 11, ["z"] = 17, ["name"] = "farming:straw"}, {["x"] = 3, ["meta"] = {["fields"] = {}, ["inventory"] = {}}, ["param2"] = 1, ["y"] = 11, ["param1"] = 125, ["z"] = 18, ["name"] = "cottages:roof_connector_straw"}, {["x"] = 3, ["meta"] = {["fields"] = {}, ["inventory"] = {}}, ["param2"] = 1, ["y"] = 11, ["param1"] = 109, ["z"] = 19, ["name"] = "cottages:roof_connector_straw"}, {["x"] = 3, ["meta"] = {["fields"] = {}, ["inventory"] = {}}, ["param2"] = 1, ["y"] = 11, ["param1"] = 93, ["z"] = 20, ["name"] = "cottages:roof_straw"}, {["x"] = 3, ["meta"] = {["fields"] = {}, ["inventory"] = {}}, ["y"] = 12, ["z"] = 15, ["name"] = "farming:straw"}, {["x"] = 3, ["meta"] = {["fields"] = {}, ["inventory"] = {}}, ["y"] = 12, ["z"] = 16, ["name"] = "farming:straw"}, {["x"] = 4, ["meta"] = {["fields"] = {}, ["inventory"] = {}}, ["param2"] = 18, ["y"] = 0, ["z"] = 12, ["name"] = "default:pinetree"}, {["x"] = 4, ["meta"] = {["fields"] = {}, ["inventory"] = {}}, ["param2"] = 12, ["y"] = 0, ["z"] = 19, ["name"] = "default:pinetree"}, {["x"] = 4, ["meta"] = {["fields"] = {}, ["inventory"] = {}}, ["y"] = 1, ["param1"] = 170, ["z"] = 12, ["name"] = "default:glass"}, {["x"] = 4, ["meta"] = {["fields"] = {}, ["inventory"] = {}}, ["y"] = 1, ["z"] = 19, ["name"] = "fachwerk:brick_1"}, {["x"] = 4, ["meta"] = {["fields"] = {}, ["inventory"] = {}}, ["y"] = 2, ["z"] = 12, ["name"] = "fachwerk:brick"}, {["x"] = 4, ["meta"] = {["fields"] = {}, ["inventory"] = {}}, ["y"] = 2, ["z"] = 19, ["name"] = "fachwerk:brick"}, {["x"] = 4, ["meta"] = {["fields"] = {}, ["inventory"] = {}}, ["param2"] = 8, ["y"] = 3, ["param1"] = 187, ["z"] = 11, ["name"] = "stairs:slab_wood"}, {["x"] = 4, ["meta"] = {["fields"] = {}, ["inventory"] = {}}, ["y"] = 3, ["z"] = 12, ["name"] = "default:wood"}, {["x"] = 4, ["meta"] = {["fields"] = {}, ["inventory"] = {}}, ["y"] = 3, ["param1"] = 153, ["z"] = 13, ["name"] = "stairs:slab_wood"}, {["x"] = 4, ["meta"] = {["fields"] = {}, ["inventory"] = {}}, ["y"] = 3, ["param1"] = 136, ["z"] = 14, ["name"] = "stairs:slab_wood"}, {["x"] = 4, ["meta"] = {["fields"] = {}, ["inventory"] = {}}, ["y"] = 3, ["param1"] = 119, ["z"] = 15, ["name"] = "stairs:slab_wood"}, {["x"] = 4, ["meta"] = {["fields"] = {}, ["inventory"] = {}}, ["y"] = 3, ["param1"] = 102, ["z"] = 16, ["name"] = "stairs:slab_wood"}, {["x"] = 4, ["meta"] = {["fields"] = {}, ["inventory"] = {}}, ["y"] = 3, ["param1"] = 102, ["z"] = 17, ["name"] = "stairs:slab_wood"}, {["x"] = 4, ["meta"] = {["fields"] = {}, ["inventory"] = {}}, ["y"] = 3, ["param1"] = 119, ["z"] = 18, ["name"] = "stairs:slab_wood"}, {["x"] = 4, ["meta"] = {["fields"] = {}, ["inventory"] = {}}, ["y"] = 3, ["z"] = 19, ["name"] = "default:wood"}, {["x"] = 4, ["meta"] = {["fields"] = {}, ["inventory"] = {}}, ["param2"] = 4, ["y"] = 3, ["param1"] = 187, ["z"] = 20, ["name"] = "stairs:slab_wood"}, {["x"] = 4, ["meta"] = {["fields"] = {}, ["inventory"] = {}}, ["y"] = 4, ["z"] = 11, ["name"] = "fachwerk:brick"}, {["x"] = 4, ["meta"] = {["fields"] = {}, ["inventory"] = {}}, ["y"] = 4, ["z"] = 20, ["name"] = "fachwerk:brick"}, {["x"] = 4, ["meta"] = {["fields"] = {}, ["inventory"] = {}}, ["y"] = 5, ["param1"] = 122, ["z"] = 11, ["name"] = "default:glass"}, {["x"] = 4, ["meta"] = {["fields"] = {}, ["inventory"] = {}}, ["y"] = 5, ["z"] = 20, ["name"] = "fachwerk:brick"}, {["x"] = 4, ["meta"] = {["fields"] = {}, ["inventory"] = {}}, ["y"] = 6, ["z"] = 9, ["name"] = "farming:straw"}, {["x"] = 4, ["meta"] = {["fields"] = {}, ["inventory"] = {}}, ["y"] = 6, ["z"] = 11, ["name"] = "fachwerk:brick"}, {["x"] = 4, ["meta"] = {["fields"] = {}, ["inventory"] = {}}, ["y"] = 6, ["param1"] = 88, ["z"] = 12, ["name"] = "stairs:slab_wood"}, {["x"] = 4, ["meta"] = {["fields"] = {}, ["inventory"] = {}}, ["y"] = 6, ["param1"] = 103, ["z"] = 13, ["name"] = "stairs:slab_wood"}, {["x"] = 4, ["meta"] = {["fields"] = {}, ["inventory"] = {}}, ["y"] = 6, ["param1"] = 86, ["z"] = 14, ["name"] = "stairs:slab_wood"}, {["x"] = 4, ["meta"] = {["fields"] = {}, ["inventory"] = {}}, ["y"] = 6, ["param1"] = 69, ["z"] = 15, ["name"] = "stairs:slab_wood"}, {["x"] = 4, ["meta"] = {["fields"] = {}, ["inventory"] = {}}, ["y"] = 6, ["param1"] = 86, ["z"] = 16, ["name"] = "stairs:slab_wood"}, {["x"] = 4, ["meta"] = {["fields"] = {}, ["inventory"] = {}}, ["y"] = 6, ["param1"] = 87, ["z"] = 17, ["name"] = "stairs:slab_wood"}, {["x"] = 4, ["meta"] = {["fields"] = {}, ["inventory"] = {}}, ["y"] = 6, ["param1"] = 103, ["z"] = 18, ["name"] = "stairs:slab_wood"}, {["x"] = 4, ["meta"] = {["fields"] = {}, ["inventory"] = {}}, ["y"] = 6, ["param1"] = 120, ["z"] = 19, ["name"] = "stairs:slab_wood"}, {["x"] = 4, ["meta"] = {["fields"] = {}, ["inventory"] = {}}, ["y"] = 6, ["z"] = 20, ["name"] = "fachwerk:brick"}, {["x"] = 4, ["meta"] = {["fields"] = {}, ["inventory"] = {}}, ["y"] = 6, ["z"] = 22, ["name"] = "farming:straw"}, {["x"] = 4, ["meta"] = {["fields"] = {}, ["inventory"] = {}}, ["y"] = 7, ["z"] = 10, ["name"] = "farming:straw"}, {["x"] = 4, ["meta"] = {["fields"] = {}, ["inventory"] = {}}, ["y"] = 7, ["z"] = 11, ["name"] = "fachwerk:brick"}, {["x"] = 4, ["meta"] = {["fields"] = {}, ["inventory"] = {}}, ["y"] = 7, ["z"] = 20, ["name"] = "fachwerk:brick"}, {["x"] = 4, ["meta"] = {["fields"] = {}, ["inventory"] = {}}, ["y"] = 7, ["z"] = 21, ["name"] = "farming:straw"}, {["x"] = 4, ["meta"] = {["fields"] = {}, ["inventory"] = {}}, ["y"] = 8, ["z"] = 11, ["name"] = "farming:straw"}, {["x"] = 4, ["meta"] = {["fields"] = {}, ["inventory"] = {}}, ["y"] = 8, ["z"] = 20, ["name"] = "farming:straw"}, {["x"] = 4, ["meta"] = {["fields"] = {}, ["inventory"] = {}}, ["y"] = 9, ["z"] = 12, ["name"] = "farming:straw"}, {["x"] = 4, ["meta"] = {["fields"] = {}, ["inventory"] = {}}, ["param2"] = 1, ["y"] = 9, ["param1"] = 86, ["z"] = 13, ["name"] = "stairs:slab_wood"}, {["x"] = 4, ["meta"] = {["fields"] = {}, ["inventory"] = {}}, ["param2"] = 1, ["y"] = 9, ["param1"] = 103, ["z"] = 14, ["name"] = "stairs:slab_wood"}, {["x"] = 4, ["meta"] = {["fields"] = {}, ["inventory"] = {}}, ["param2"] = 1, ["y"] = 9, ["param1"] = 120, ["z"] = 15, ["name"] = "stairs:slab_wood"}, {["x"] = 4, ["meta"] = {["fields"] = {}, ["inventory"] = {}}, ["param2"] = 1, ["y"] = 9, ["param1"] = 137, ["z"] = 16, ["name"] = "stairs:slab_wood"}, {["x"] = 4, ["meta"] = {["fields"] = {}, ["inventory"] = {}}, ["param2"] = 1, ["y"] = 9, ["param1"] = 122, ["z"] = 17, ["name"] = "stairs:slab_wood"}, {["x"] = 4, ["meta"] = {["fields"] = {}, ["inventory"] = {}}, ["param2"] = 1, ["y"] = 9, ["param1"] = 106, ["z"] = 18, ["name"] = "stairs:slab_wood"}, {["x"] = 4, ["meta"] = {["fields"] = {}, ["inventory"] = {}}, ["y"] = 9, ["z"] = 19, ["name"] = "farming:straw"}, {["x"] = 4, ["meta"] = {["fields"] = {}, ["inventory"] = {}}, ["y"] = 10, ["z"] = 13, ["name"] = "farming:straw"}, {["x"] = 4, ["meta"] = {["fields"] = {}, ["inventory"] = {}}, ["y"] = 10, ["param1"] = 107, ["z"] = 19, ["name"] = "default:glass"}, {["x"] = 4, ["meta"] = {["fields"] = {}, ["inventory"] = {}}, ["y"] = 11, ["z"] = 14, ["name"] = "farming:straw"}, {["x"] = 4, ["meta"] = {["fields"] = {}, ["inventory"] = {}}, ["param2"] = 8, ["y"] = 11, ["param1"] = 108, ["z"] = 18, ["name"] = "cottages:roof_flat_straw"}, {["x"] = 4, ["meta"] = {["fields"] = {}, ["inventory"] = {}}, ["y"] = 11, ["z"] = 19, ["name"] = "fachwerk:brick"}, {["x"] = 4, ["meta"] = {["fields"] = {}, ["inventory"] = {}}, ["y"] = 12, ["z"] = 15, ["name"] = "farming:straw"}, {["x"] = 4, ["meta"] = {["fields"] = {}, ["inventory"] = {}}, ["y"] = 12, ["z"] = 16, ["name"] = "farming:straw"}, {["x"] = 4, ["meta"] = {["fields"] = {}, ["inventory"] = {}}, ["param2"] = 2, ["y"] = 12, ["param1"] = 109, ["z"] = 17, ["name"] = "cottages:roof_flat_straw"}, {["x"] = 4, ["meta"] = {["fields"] = {}, ["inventory"] = {}}, ["param2"] = 2, ["y"] = 12, ["param1"] = 93, ["z"] = 18, ["name"] = "cottages:roof_flat_straw"}, {["x"] = 4, ["meta"] = {["fields"] = {}, ["inventory"] = {}}, ["param2"] = 2, ["y"] = 12, ["param1"] = 77, ["z"] = 19, ["name"] = "cottages:roof_flat_straw"}, {["x"] = 4, ["meta"] = {["fields"] = {}, ["inventory"] = {}}, ["param2"] = 2, ["y"] = 12, ["param1"] = 61, ["z"] = 20, ["name"] = "cottages:roof_flat_straw"}, {["x"] = 5, ["meta"] = {["fields"] = {}, ["inventory"] = {}}, ["y"] = 0, ["param1"] = 45, ["z"] = 4, ["name"] = "default:papyrus"}, {["x"] = 5, ["meta"] = {["fields"] = {}, ["inventory"] = {}}, ["param2"] = 12, ["y"] = 0, ["z"] = 12, ["name"] = "default:pinetree"}, {["x"] = 5, ["meta"] = {["fields"] = {}, ["inventory"] = {}}, ["param2"] = 3, ["y"] = 0, ["param1"] = 138, ["z"] = 19, ["name"] = "doors:door_wood_b_2"}, {["x"] = 5, ["meta"] = {["fields"] = {}, ["inventory"] = {}}, ["y"] = 1, ["param1"] = 61, ["z"] = 4, ["name"] = "default:papyrus"}, {["x"] = 5, ["meta"] = {["fields"] = {}, ["inventory"] = {}}, ["y"] = 1, ["z"] = 12, ["name"] = "fachwerk:brick"}, {["x"] = 5, ["meta"] = {["fields"] = {}, ["inventory"] = {}}, ["param2"] = 3, ["y"] = 1, ["param1"] = 154, ["z"] = 19, ["name"] = "doors:door_wood_t_2"}, {["x"] = 5, ["meta"] = {["fields"] = {}, ["inventory"] = {}}, ["y"] = 2, ["z"] = 12, ["name"] = "fachwerk:brick_2"}, {["x"] = 5, ["meta"] = {["fields"] = {}, ["inventory"] = {}}, ["y"] = 2, ["z"] = 19, ["name"] = "fachwerk:brick"}, {["x"] = 5, ["meta"] = {["fields"] = {}, ["inventory"] = {}}, ["param2"] = 8, ["y"] = 3, ["param1"] = 171, ["z"] = 11, ["name"] = "stairs:slab_wood"}, {["x"] = 5, ["meta"] = {["fields"] = {}, ["inventory"] = {}}, ["y"] = 3, ["z"] = 12, ["name"] = "default:wood"}, {["x"] = 5, ["meta"] = {["fields"] = {}, ["inventory"] = {}}, ["y"] = 3, ["param1"] = 136, ["z"] = 13, ["name"] = "stairs:slab_wood"}, {["x"] = 5, ["meta"] = {["fields"] = {}, ["inventory"] = {}}, ["y"] = 3, ["param1"] = 119, ["z"] = 14, ["name"] = "stairs:slab_wood"}, {["x"] = 5, ["meta"] = {["fields"] = {}, ["inventory"] = {}}, ["y"] = 3, ["z"] = 15, ["name"] = "default:wood"}, {["x"] = 5, ["meta"] = {["fields"] = {}, ["inventory"] = {}}, ["y"] = 3, ["z"] = 16, ["name"] = "default:wood"}, {["x"] = 5, ["meta"] = {["fields"] = {}, ["inventory"] = {}}, ["y"] = 3, ["z"] = 17, ["name"] = "default:wood"}, {["x"] = 5, ["meta"] = {["fields"] = {}, ["inventory"] = {}}, ["y"] = 3, ["z"] = 18, ["name"] = "default:wood"}, {["x"] = 5, ["meta"] = {["fields"] = {}, ["inventory"] = {}}, ["y"] = 3, ["z"] = 19, ["name"] = "default:wood"}, {["x"] = 5, ["meta"] = {["fields"] = {}, ["inventory"] = {}}, ["param2"] = 4, ["y"] = 3, ["param1"] = 171, ["z"] = 20, ["name"] = "stairs:slab_wood"}, {["x"] = 5, ["meta"] = {["fields"] = {}, ["inventory"] = {}}, ["y"] = 4, ["z"] = 11, ["name"] = "fachwerk:brick"}, {["x"] = 5, ["meta"] = {["fields"] = {}, ["inventory"] = {}}, ["y"] = 4, ["param1"] = 85, ["z"] = 15, ["name"] = "fences:fence_wood_2"}, {["x"] = 5, ["meta"] = {["fields"] = {}, ["inventory"] = {}}, ["y"] = 4, ["param1"] = 86, ["z"] = 16, ["name"] = "fences:fence_wood_3"}, {["x"] = 5, ["meta"] = {["fields"] = {}, ["inventory"] = {}}, ["y"] = 4, ["param1"] = 103, ["z"] = 17, ["name"] = "fences:fence_wood_3"}, {["x"] = 5, ["meta"] = {["fields"] = {}, ["inventory"] = {}}, ["y"] = 4, ["param1"] = 120, ["z"] = 18, ["name"] = "fences:fence_wood_22"}, {["x"] = 5, ["meta"] = {["fields"] = {}, ["inventory"] = {}}, ["y"] = 4, ["z"] = 20, ["name"] = "fachwerk:brick"}, {["x"] = 5, ["meta"] = {["fields"] = {}, ["inventory"] = {}}, ["y"] = 5, ["z"] = 11, ["name"] = "fachwerk:brick"}, {["x"] = 5, ["meta"] = {["fields"] = {}, ["inventory"] = {}}, ["y"] = 5, ["param1"] = 171, ["z"] = 20, ["name"] = "default:glass"}, {["x"] = 5, ["meta"] = {["fields"] = {}, ["inventory"] = {}}, ["y"] = 6, ["z"] = 9, ["name"] = "farming:straw"}, {["x"] = 5, ["meta"] = {["fields"] = {}, ["inventory"] = {}}, ["y"] = 6, ["z"] = 11, ["name"] = "fachwerk:brick"}, {["x"] = 5, ["meta"] = {["fields"] = {}, ["inventory"] = {}}, ["y"] = 6, ["param1"] = 71, ["z"] = 12, ["name"] = "stairs:slab_wood"}, {["x"] = 5, ["meta"] = {["fields"] = {}, ["inventory"] = {}}, ["y"] = 6, ["param1"] = 86, ["z"] = 13, ["name"] = "stairs:slab_wood"}, {["x"] = 5, ["meta"] = {["fields"] = {}, ["inventory"] = {}}, ["y"] = 6, ["param1"] = 69, ["z"] = 14, ["name"] = "stairs:slab_wood"}, {["x"] = 5, ["meta"] = {["fields"] = {}, ["inventory"] = {}}, ["y"] = 6, ["param1"] = 69, ["z"] = 15, ["name"] = "stairs:slab_wood"}, {["x"] = 5, ["meta"] = {["fields"] = {}, ["inventory"] = {}}, ["y"] = 6, ["param1"] = 86, ["z"] = 16, ["name"] = "stairs:slab_wood"}, {["x"] = 5, ["meta"] = {["fields"] = {}, ["inventory"] = {}}, ["y"] = 6, ["param1"] = 103, ["z"] = 17, ["name"] = "stairs:slab_wood"}, {["x"] = 5, ["meta"] = {["fields"] = {}, ["inventory"] = {}}, ["y"] = 6, ["param1"] = 120, ["z"] = 18, ["name"] = "stairs:slab_wood"}, {["x"] = 5, ["meta"] = {["fields"] = {}, ["inventory"] = {}}, ["y"] = 6, ["param1"] = 137, ["z"] = 19, ["name"] = "stairs:slab_wood"}, {["x"] = 5, ["meta"] = {["fields"] = {}, ["inventory"] = {}}, ["y"] = 6, ["z"] = 20, ["name"] = "fachwerk:brick"}, {["x"] = 5, ["meta"] = {["fields"] = {}, ["inventory"] = {}}, ["y"] = 6, ["z"] = 22, ["name"] = "farming:straw"}, {["x"] = 5, ["meta"] = {["fields"] = {}, ["inventory"] = {}}, ["y"] = 7, ["z"] = 10, ["name"] = "farming:straw"}, {["x"] = 5, ["meta"] = {["fields"] = {}, ["inventory"] = {}}, ["y"] = 7, ["z"] = 11, ["name"] = "fachwerk:brick"}, {["x"] = 5, ["meta"] = {["fields"] = {}, ["inventory"] = {}}, ["y"] = 7, ["z"] = 20, ["name"] = "fachwerk:brick"}, {["x"] = 5, ["meta"] = {["fields"] = {}, ["inventory"] = {}}, ["y"] = 7, ["z"] = 21, ["name"] = "farming:straw"}, {["x"] = 5, ["meta"] = {["fields"] = {}, ["inventory"] = {}}, ["y"] = 8, ["z"] = 11, ["name"] = "farming:straw"}, {["x"] = 5, ["meta"] = {["fields"] = {}, ["inventory"] = {}}, ["y"] = 8, ["z"] = 20, ["name"] = "farming:straw"}, {["x"] = 5, ["meta"] = {["fields"] = {}, ["inventory"] = {}}, ["y"] = 9, ["z"] = 12, ["name"] = "farming:straw"}, {["x"] = 5, ["meta"] = {["fields"] = {}, ["inventory"] = {}}, ["param2"] = 1, ["y"] = 9, ["param1"] = 70, ["z"] = 13, ["name"] = "stairs:slab_wood"}, {["x"] = 5, ["meta"] = {["fields"] = {}, ["inventory"] = {}}, ["param2"] = 1, ["y"] = 9, ["param1"] = 87, ["z"] = 14, ["name"] = "stairs:slab_wood"}, {["x"] = 5, ["meta"] = {["fields"] = {}, ["inventory"] = {}}, ["param2"] = 1, ["y"] = 9, ["param1"] = 104, ["z"] = 15, ["name"] = "beds:bed_bottom"}, {["x"] = 5, ["meta"] = {["fields"] = {}, ["inventory"] = {}}, ["param2"] = 1, ["y"] = 9, ["param1"] = 121, ["z"] = 16, ["name"] = "beds:bed_bottom"}, {["x"] = 5, ["meta"] = {["fields"] = {}, ["inventory"] = {}}, ["param2"] = 1, ["y"] = 9, ["param1"] = 106, ["z"] = 17, ["name"] = "stairs:slab_wood"}, {["x"] = 5, ["meta"] = {["fields"] = {}, ["inventory"] = {}}, ["param2"] = 1, ["y"] = 9, ["param1"] = 91, ["z"] = 18, ["name"] = "stairs:slab_wood"}, {["x"] = 5, ["meta"] = {["fields"] = {}, ["inventory"] = {}}, ["y"] = 9, ["z"] = 19, ["name"] = "farming:straw"}, {["x"] = 5, ["meta"] = {["fields"] = {}, ["inventory"] = {}}, ["y"] = 10, ["z"] = 13, ["name"] = "farming:straw"}, {["x"] = 5, ["meta"] = {["fields"] = {}, ["inventory"] = {}}, ["param2"] = 8, ["y"] = 10, ["param1"] = 108, ["z"] = 18, ["name"] = "cottages:roof_flat_straw"}, {["x"] = 5, ["meta"] = {["fields"] = {}, ["inventory"] = {}}, ["y"] = 10, ["z"] = 19, ["name"] = "fachwerk:brick"}, {["x"] = 5, ["meta"] = {["fields"] = {}, ["inventory"] = {}}, ["y"] = 11, ["z"] = 14, ["name"] = "farming:straw"}, {["x"] = 5, ["meta"] = {["fields"] = {}, ["inventory"] = {}}, ["y"] = 11, ["z"] = 17, ["name"] = "farming:straw"}, {["x"] = 5, ["meta"] = {["fields"] = {}, ["inventory"] = {}}, ["param2"] = 3, ["y"] = 11, ["param1"] = 93, ["z"] = 18, ["name"] = "cottages:roof_connector_straw"}, {["x"] = 5, ["meta"] = {["fields"] = {}, ["inventory"] = {}}, ["param2"] = 3, ["y"] = 11, ["param1"] = 77, ["z"] = 19, ["name"] = "cottages:roof_connector_straw"}, {["x"] = 5, ["meta"] = {["fields"] = {}, ["inventory"] = {}}, ["param2"] = 3, ["y"] = 11, ["param1"] = 77, ["z"] = 20, ["name"] = "cottages:roof_straw"}, {["x"] = 5, ["meta"] = {["fields"] = {}, ["inventory"] = {}}, ["y"] = 12, ["z"] = 15, ["name"] = "farming:straw"}, {["x"] = 5, ["meta"] = {["fields"] = {}, ["inventory"] = {}}, ["y"] = 12, ["z"] = 16, ["name"] = "farming:straw"}, {["x"] = 6, ["meta"] = {["fields"] = {}, ["inventory"] = {}}, ["param2"] = 18, ["y"] = 0, ["z"] = 12, ["name"] = "default:pinetree"}, {["x"] = 6, ["meta"] = {["fields"] = {}, ["inventory"] = {}}, ["y"] = 0, ["param1"] = 87, ["z"] = 17, ["name"] = "stairs:slab_wood"}, {["x"] = 6, ["meta"] = {["fields"] = {}, ["inventory"] = {}}, ["param2"] = 18, ["y"] = 0, ["z"] = 19, ["name"] = "default:pinetree"}, {["x"] = 6, ["meta"] = {["fields"] = {}, ["inventory"] = {}}, ["y"] = 1, ["z"] = 12, ["name"] = "fachwerk:brick"}, {["x"] = 6, ["meta"] = {["fields"] = {}, ["inventory"] = {}}, ["y"] = 1, ["param1"] = 102, ["z"] = 16, ["name"] = "stairs:slab_wood"}, {["x"] = 6, ["meta"] = {["fields"] = {}, ["inventory"] = {}}, ["y"] = 1, ["z"] = 19, ["name"] = "fachwerk:brick"}, {["x"] = 6, ["meta"] = {["fields"] = {}, ["inventory"] = {}}, ["y"] = 2, ["z"] = 12, ["name"] = "fachwerk:brick"}, {["x"] = 6, ["meta"] = {["fields"] = {}, ["inventory"] = {}}, ["y"] = 2, ["param1"] = 102, ["z"] = 15, ["name"] = "stairs:slab_wood"}, {["x"] = 6, ["meta"] = {["fields"] = {}, ["inventory"] = {}}, ["y"] = 2, ["z"] = 19, ["name"] = "fachwerk:brick"}, {["x"] = 6, ["meta"] = {["fields"] = {}, ["inventory"] = {}}, ["param2"] = 8, ["y"] = 3, ["param1"] = 155, ["z"] = 11, ["name"] = "stairs:slab_wood"}, {["x"] = 6, ["meta"] = {["fields"] = {}, ["inventory"] = {}}, ["y"] = 3, ["z"] = 12, ["name"] = "default:wood"}, {["x"] = 6, ["meta"] = {["fields"] = {}, ["inventory"] = {}}, ["y"] = 3, ["param1"] = 119, ["z"] = 13, ["name"] = "stairs:slab_wood"}, {["x"] = 6, ["meta"] = {["fields"] = {}, ["inventory"] = {}}, ["y"] = 3, ["param1"] = 102, ["z"] = 14, ["name"] = "stairs:slab_wood"}, {["x"] = 6, ["meta"] = {["fields"] = {}, ["inventory"] = {}}, ["y"] = 3, ["z"] = 18, ["name"] = "default:wood"}, {["x"] = 6, ["meta"] = {["fields"] = {}, ["inventory"] = {}}, ["y"] = 3, ["z"] = 19, ["name"] = "default:wood"}, {["x"] = 6, ["meta"] = {["fields"] = {}, ["inventory"] = {}}, ["param2"] = 4, ["y"] = 3, ["param1"] = 187, ["z"] = 20, ["name"] = "stairs:slab_wood"}, {["x"] = 6, ["meta"] = {["fields"] = {}, ["inventory"] = {}}, ["y"] = 4, ["z"] = 11, ["name"] = "fachwerk:brick"}, {["x"] = 6, ["meta"] = {["fields"] = {}, ["inventory"] = {}}, ["y"] = 4, ["param1"] = 136, ["z"] = 18, ["name"] = "fences:fence_wood_32"}, {["x"] = 6, ["meta"] = {["fields"] = {}, ["inventory"] = {}}, ["y"] = 4, ["z"] = 20, ["name"] = "fachwerk:brick_1"}, {["x"] = 6, ["meta"] = {["fields"] = {}, ["inventory"] = {}}, ["y"] = 5, ["z"] = 11, ["name"] = "fachwerk:brick"}, {["x"] = 6, ["meta"] = {["fields"] = {}, ["inventory"] = {}}, ["y"] = 6, ["z"] = 9, ["name"] = "farming:straw"}, {["x"] = 6, ["meta"] = {["fields"] = {}, ["inventory"] = {}}, ["y"] = 6, ["z"] = 11, ["name"] = "fachwerk:brick"}, {["x"] = 6, ["meta"] = {["fields"] = {}, ["inventory"] = {}}, ["y"] = 6, ["param1"] = 54, ["z"] = 12, ["name"] = "stairs:slab_wood"}, {["x"] = 6, ["meta"] = {["fields"] = {}, ["inventory"] = {}}, ["y"] = 6, ["param1"] = 69, ["z"] = 13, ["name"] = "stairs:slab_wood"}, {["x"] = 6, ["meta"] = {["fields"] = {}, ["inventory"] = {}}, ["y"] = 6, ["param1"] = 68, ["z"] = 14, ["name"] = "stairs:slab_wood"}, {["x"] = 6, ["meta"] = {["fields"] = {}, ["inventory"] = {}}, ["y"] = 6, ["param1"] = 85, ["z"] = 15, ["name"] = "stairs:slab_wood"}, {["x"] = 6, ["meta"] = {["fields"] = {}, ["inventory"] = {}}, ["y"] = 6, ["param1"] = 102, ["z"] = 16, ["name"] = "stairs:slab_wood"}, {["x"] = 6, ["meta"] = {["fields"] = {}, ["inventory"] = {}}, ["y"] = 6, ["param1"] = 119, ["z"] = 17, ["name"] = "stairs:slab_wood"}, {["x"] = 6, ["meta"] = {["fields"] = {}, ["inventory"] = {}}, ["y"] = 6, ["param1"] = 136, ["z"] = 18, ["name"] = "stairs:slab_wood"}, {["x"] = 6, ["meta"] = {["fields"] = {}, ["inventory"] = {}}, ["y"] = 6, ["param1"] = 153, ["z"] = 19, ["name"] = "stairs:slab_wood"}, {["x"] = 6, ["meta"] = {["fields"] = {}, ["inventory"] = {}}, ["y"] = 6, ["z"] = 20, ["name"] = "fachwerk:brick"}, {["x"] = 6, ["meta"] = {["fields"] = {}, ["inventory"] = {}}, ["y"] = 6, ["z"] = 22, ["name"] = "farming:straw"}, {["x"] = 6, ["meta"] = {["fields"] = {}, ["inventory"] = {}}, ["y"] = 7, ["z"] = 10, ["name"] = "farming:straw"}, {["x"] = 6, ["meta"] = {["fields"] = {}, ["inventory"] = {}}, ["y"] = 7, ["z"] = 11, ["name"] = "fachwerk:brick"}, {["x"] = 6, ["meta"] = {["fields"] = {}, ["inventory"] = {}}, ["y"] = 7, ["z"] = 20, ["name"] = "fachwerk:brick"}, {["x"] = 6, ["meta"] = {["fields"] = {}, ["inventory"] = {}}, ["y"] = 7, ["z"] = 21, ["name"] = "farming:straw"}, {["x"] = 6, ["meta"] = {["fields"] = {}, ["inventory"] = {}}, ["y"] = 8, ["z"] = 11, ["name"] = "farming:straw"}, {["x"] = 6, ["meta"] = {["fields"] = {}, ["inventory"] = {}}, ["y"] = 8, ["z"] = 20, ["name"] = "farming:straw"}, {["x"] = 6, ["meta"] = {["fields"] = {}, ["inventory"] = {}}, ["y"] = 9, ["z"] = 12, ["name"] = "farming:straw"}, {["x"] = 6, ["meta"] = {["fields"] = {}, ["inventory"] = {}}, ["param2"] = 1, ["y"] = 9, ["param1"] = 53, ["z"] = 13, ["name"] = "stairs:slab_wood"}, {["x"] = 6, ["meta"] = {["fields"] = {}, ["inventory"] = {}}, ["param2"] = 1, ["y"] = 9, ["param1"] = 70, ["z"] = 14, ["name"] = "stairs:slab_wood"}, {["x"] = 6, ["meta"] = {["fields"] = {}, ["inventory"] = {}}, ["param2"] = 1, ["y"] = 9, ["param1"] = 87, ["z"] = 15, ["name"] = "beds:bed_top"}, {["x"] = 6, ["meta"] = {["fields"] = {}, ["inventory"] = {}}, ["param2"] = 1, ["y"] = 9, ["param1"] = 104, ["z"] = 16, ["name"] = "beds:bed_top"}, {["x"] = 6, ["meta"] = {["fields"] = {}, ["inventory"] = {}}, ["param2"] = 1, ["y"] = 9, ["param1"] = 89, ["z"] = 17, ["name"] = "stairs:slab_wood"}, {["x"] = 6, ["meta"] = {["fields"] = {}, ["inventory"] = {}}, ["param2"] = 1, ["y"] = 9, ["param1"] = 90, ["z"] = 18, ["name"] = "stairs:slab_wood"}, {["x"] = 6, ["meta"] = {["fields"] = {}, ["inventory"] = {}}, ["y"] = 9, ["z"] = 19, ["name"] = "farming:straw"}, {["x"] = 6, ["meta"] = {["fields"] = {}, ["inventory"] = {}}, ["y"] = 10, ["z"] = 13, ["name"] = "farming:straw"}, {["x"] = 6, ["meta"] = {["fields"] = {}, ["inventory"] = {}}, ["y"] = 10, ["z"] = 18, ["name"] = "farming:straw"}, {["x"] = 6, ["meta"] = {["fields"] = {}, ["inventory"] = {}}, ["param2"] = 3, ["y"] = 10, ["param1"] = 109, ["z"] = 19, ["name"] = "cottages:roof_connector_straw"}, {["x"] = 6, ["meta"] = {["fields"] = {}, ["inventory"] = {}}, ["param2"] = 3, ["y"] = 10, ["param1"] = 109, ["z"] = 20, ["name"] = "cottages:roof_straw"}, {["x"] = 6, ["meta"] = {["fields"] = {}, ["inventory"] = {}}, ["y"] = 11, ["z"] = 14, ["name"] = "farming:straw"}, {["x"] = 6, ["meta"] = {["fields"] = {}, ["inventory"] = {}}, ["y"] = 11, ["z"] = 17, ["name"] = "farming:straw"}, {["x"] = 6, ["meta"] = {["fields"] = {}, ["inventory"] = {}}, ["y"] = 12, ["z"] = 15, ["name"] = "farming:straw"}, {["x"] = 6, ["meta"] = {["fields"] = {}, ["inventory"] = {}}, ["y"] = 12, ["z"] = 16, ["name"] = "farming:straw"}, {["x"] = 7, ["meta"] = {["fields"] = {}, ["inventory"] = {}}, ["y"] = 0, ["param1"] = 77, ["z"] = 8, ["name"] = "default:papyrus"}, {["x"] = 7, ["meta"] = {["fields"] = {}, ["inventory"] = {}}, ["param2"] = 12, ["y"] = 0, ["z"] = 12, ["name"] = "default:pinetree"}, {["x"] = 7, ["meta"] = {["fields"] = {}, ["inventory"] = {}}, ["param2"] = 9, ["y"] = 0, ["z"] = 13, ["name"] = "default:pinetree"}, {["x"] = 7, ["meta"] = {["fields"] = {}, ["inventory"] = {}}, ["param2"] = 9, ["y"] = 0, ["z"] = 14, ["name"] = "default:pinetree"}, {["x"] = 7, ["meta"] = {["fields"] = {}, ["inventory"] = {}}, ["param2"] = 9, ["y"] = 0, ["z"] = 15, ["name"] = "default:pinetree"}, {["x"] = 7, ["meta"] = {["fields"] = {}, ["inventory"] = {}}, ["param2"] = 9, ["y"] = 0, ["z"] = 16, ["name"] = "default:pinetree"}, {["x"] = 7, ["meta"] = {["fields"] = {}, ["inventory"] = {}}, ["param2"] = 9, ["y"] = 0, ["z"] = 17, ["name"] = "default:pinetree"}, {["x"] = 7, ["meta"] = {["fields"] = {}, ["inventory"] = {}}, ["param2"] = 9, ["y"] = 0, ["z"] = 18, ["name"] = "default:pinetree"}, {["x"] = 7, ["meta"] = {["fields"] = {}, ["inventory"] = {}}, ["param2"] = 2, ["y"] = 0, ["z"] = 19, ["name"] = "default:pinetree"}, {["x"] = 7, ["meta"] = {["fields"] = {}, ["inventory"] = {}}, ["y"] = 1, ["param1"] = 93, ["z"] = 8, ["name"] = "default:papyrus"}, {["x"] = 7, ["meta"] = {["fields"] = {}, ["inventory"] = {}}, ["y"] = 1, ["z"] = 12, ["name"] = "fachwerk:clay"}, {["x"] = 7, ["meta"] = {["fields"] = {}, ["inventory"] = {}}, ["y"] = 1, ["z"] = 13, ["name"] = "fachwerk:clay"}, {["x"] = 7, ["meta"] = {["fields"] = {}, ["inventory"] = {}}, ["y"] = 1, ["z"] = 14, ["name"] = "fachwerk:clay"}, {["x"] = 7, ["meta"] = {["fields"] = {}, ["inventory"] = {}}, ["y"] = 1, ["z"] = 15, ["name"] = "fachwerk:clay"}, {["x"] = 7, ["meta"] = {["fields"] = {}, ["inventory"] = {}}, ["y"] = 1, ["z"] = 16, ["name"] = "fachwerk:clay"}, {["x"] = 7, ["meta"] = {["fields"] = {}, ["inventory"] = {}}, ["y"] = 1, ["z"] = 17, ["name"] = "fachwerk:clay"}, {["x"] = 7, ["meta"] = {["fields"] = {}, ["inventory"] = {}}, ["y"] = 1, ["z"] = 18, ["name"] = "fachwerk:clay"}, {["x"] = 7, ["meta"] = {["fields"] = {}, ["inventory"] = {}}, ["param2"] = 2, ["y"] = 1, ["z"] = 19, ["name"] = "default:pinetree"}, {["x"] = 7, ["meta"] = {["fields"] = {}, ["inventory"] = {}}, ["y"] = 2, ["z"] = 12, ["name"] = "fachwerk:clay"}, {["x"] = 7, ["meta"] = {["fields"] = {}, ["inventory"] = {}}, ["y"] = 2, ["z"] = 13, ["name"] = "fachwerk:clay"}, {["x"] = 7, ["meta"] = {["fields"] = {}, ["inventory"] = {}}, ["y"] = 2, ["z"] = 14, ["name"] = "fachwerk:clay"}, {["x"] = 7, ["meta"] = {["fields"] = {}, ["inventory"] = {}}, ["y"] = 2, ["z"] = 15, ["name"] = "fachwerk:clay"}, {["x"] = 7, ["meta"] = {["fields"] = {}, ["inventory"] = {}}, ["y"] = 2, ["z"] = 16, ["name"] = "fachwerk:clay"}, {["x"] = 7, ["meta"] = {["fields"] = {}, ["inventory"] = {}}, ["y"] = 2, ["z"] = 17, ["name"] = "fachwerk:clay"}, {["x"] = 7, ["meta"] = {["fields"] = {}, ["inventory"] = {}}, ["y"] = 2, ["z"] = 18, ["name"] = "fachwerk:clay"}, {["x"] = 7, ["meta"] = {["fields"] = {}, ["inventory"] = {}}, ["param2"] = 2, ["y"] = 2, ["z"] = 19, ["name"] = "default:pinetree"}, {["x"] = 7, ["meta"] = {["fields"] = {}, ["inventory"] = {}}, ["param2"] = 5, ["y"] = 2, ["z"] = 20, ["name"] = "torches:wall"}, {["x"] = 7, ["meta"] = {["fields"] = {}, ["inventory"] = {}}, ["param2"] = 8, ["y"] = 3, ["param1"] = 155, ["z"] = 11, ["name"] = "stairs:slab_wood"}, {["x"] = 7, ["meta"] = {["fields"] = {}, ["inventory"] = {}}, ["y"] = 3, ["z"] = 12, ["name"] = "default:wood"}, {["x"] = 7, ["meta"] = {["fields"] = {}, ["inventory"] = {}}, ["y"] = 3, ["z"] = 13, ["name"] = "default:wood"}, {["x"] = 7, ["meta"] = {["fields"] = {}, ["inventory"] = {}}, ["y"] = 3, ["z"] = 14, ["name"] = "default:wood"}, {["x"] = 7, ["meta"] = {["fields"] = {}, ["inventory"] = {}}, ["y"] = 3, ["z"] = 15, ["name"] = "default:wood"}, {["x"] = 7, ["meta"] = {["fields"] = {}, ["inventory"] = {}}, ["y"] = 3, ["z"] = 16, ["name"] = "default:wood"}, {["x"] = 7, ["meta"] = {["fields"] = {}, ["inventory"] = {}}, ["y"] = 3, ["z"] = 17, ["name"] = "default:wood"}, {["x"] = 7, ["meta"] = {["fields"] = {}, ["inventory"] = {}}, ["y"] = 3, ["z"] = 18, ["name"] = "default:wood"}, {["x"] = 7, ["meta"] = {["fields"] = {}, ["inventory"] = {}}, ["y"] = 3, ["z"] = 19, ["name"] = "default:wood"}, {["x"] = 7, ["meta"] = {["fields"] = {}, ["inventory"] = {}}, ["param2"] = 4, ["y"] = 3, ["param1"] = 204, ["z"] = 20, ["name"] = "stairs:slab_wood"}, {["x"] = 7, ["meta"] = {["fields"] = {}, ["inventory"] = {}}, ["y"] = 4, ["z"] = 11, ["name"] = "fachwerk:clay"}, {["x"] = 7, ["meta"] = {["fields"] = {}, ["inventory"] = {}}, ["y"] = 4, ["z"] = 12, ["name"] = "default:wood"}, {["x"] = 7, ["meta"] = {["fields"] = {}, ["inventory"] = {}}, ["y"] = 4, ["z"] = 13, ["name"] = "default:wood"}, {["x"] = 7, ["meta"] = {["fields"] = {}, ["inventory"] = {}}, ["y"] = 4, ["z"] = 14, ["name"] = "default:wood"}, {["x"] = 7, ["meta"] = {["fields"] = {}, ["inventory"] = {}}, ["y"] = 4, ["z"] = 15, ["name"] = "default:wood"}, {["x"] = 7, ["meta"] = {["fields"] = {}, ["inventory"] = {}}, ["y"] = 4, ["z"] = 16, ["name"] = "default:wood"}, {["x"] = 7, ["meta"] = {["fields"] = {}, ["inventory"] = {}}, ["y"] = 4, ["z"] = 17, ["name"] = "default:wood"}, {["x"] = 7, ["meta"] = {["fields"] = {}, ["inventory"] = {}}, ["y"] = 4, ["z"] = 18, ["name"] = "default:wood"}, {["x"] = 7, ["meta"] = {["fields"] = {}, ["inventory"] = {}}, ["y"] = 4, ["z"] = 19, ["name"] = "default:wood"}, {["x"] = 7, ["meta"] = {["fields"] = {}, ["inventory"] = {}}, ["y"] = 4, ["z"] = 20, ["name"] = "fachwerk:clay"}, {["x"] = 7, ["meta"] = {["fields"] = {}, ["inventory"] = {}}, ["y"] = 5, ["z"] = 11, ["name"] = "fachwerk:clay"}, {["x"] = 7, ["meta"] = {["fields"] = {}, ["inventory"] = {}}, ["y"] = 5, ["z"] = 12, ["name"] = "default:wood"}, {["x"] = 7, ["meta"] = {["fields"] = {}, ["inventory"] = {}}, ["y"] = 5, ["z"] = 13, ["name"] = "default:wood"}, {["x"] = 7, ["meta"] = {["fields"] = {}, ["inventory"] = {}}, ["y"] = 5, ["z"] = 14, ["name"] = "default:wood"}, {["x"] = 7, ["meta"] = {["fields"] = {}, ["inventory"] = {}}, ["y"] = 5, ["z"] = 15, ["name"] = "default:wood"}, {["x"] = 7, ["meta"] = {["fields"] = {}, ["inventory"] = {}}, ["y"] = 5, ["z"] = 16, ["name"] = "default:wood"}, {["x"] = 7, ["meta"] = {["fields"] = {}, ["inventory"] = {}}, ["y"] = 5, ["z"] = 17, ["name"] = "default:wood"}, {["x"] = 7, ["meta"] = {["fields"] = {}, ["inventory"] = {}}, ["y"] = 5, ["z"] = 18, ["name"] = "default:wood"}, {["x"] = 7, ["meta"] = {["fields"] = {}, ["inventory"] = {}}, ["y"] = 5, ["z"] = 19, ["name"] = "default:wood"}, {["x"] = 7, ["meta"] = {["fields"] = {}, ["inventory"] = {}}, ["y"] = 5, ["z"] = 20, ["name"] = "fachwerk:clay"}, {["x"] = 7, ["meta"] = {["fields"] = {}, ["inventory"] = {}}, ["param2"] = 5, ["y"] = 5, ["z"] = 21, ["name"] = "torches:wall"}, {["x"] = 7, ["meta"] = {["fields"] = {}, ["inventory"] = {}}, ["y"] = 6, ["param1"] = 93, ["z"] = 9, ["name"] = "cottages:roof_red"}, {["x"] = 7, ["meta"] = {["fields"] = {}, ["inventory"] = {}}, ["y"] = 6, ["z"] = 11, ["name"] = "fachwerk:clay"}, {["x"] = 7, ["meta"] = {["fields"] = {}, ["inventory"] = {}}, ["y"] = 6, ["z"] = 12, ["name"] = "default:wood"}, {["x"] = 7, ["meta"] = {["fields"] = {}, ["inventory"] = {}}, ["y"] = 6, ["z"] = 13, ["name"] = "default:wood"}, {["x"] = 7, ["meta"] = {["fields"] = {}, ["inventory"] = {}}, ["y"] = 6, ["z"] = 14, ["name"] = "default:wood"}, {["x"] = 7, ["meta"] = {["fields"] = {}, ["inventory"] = {}}, ["y"] = 6, ["z"] = 15, ["name"] = "default:wood"}, {["x"] = 7, ["meta"] = {["fields"] = {}, ["inventory"] = {}}, ["y"] = 6, ["z"] = 16, ["name"] = "default:wood"}, {["x"] = 7, ["meta"] = {["fields"] = {}, ["inventory"] = {}}, ["y"] = 6, ["z"] = 17, ["name"] = "default:wood"}, {["x"] = 7, ["meta"] = {["fields"] = {}, ["inventory"] = {}}, ["y"] = 6, ["z"] = 18, ["name"] = "default:wood"}, {["x"] = 7, ["meta"] = {["fields"] = {}, ["inventory"] = {}}, ["y"] = 6, ["z"] = 19, ["name"] = "default:wood"}, {["x"] = 7, ["meta"] = {["fields"] = {}, ["inventory"] = {}}, ["y"] = 6, ["z"] = 20, ["name"] = "fachwerk:clay"}, {["x"] = 7, ["meta"] = {["fields"] = {}, ["inventory"] = {}}, ["param2"] = 2, ["y"] = 6, ["param1"] = 189, ["z"] = 22, ["name"] = "cottages:roof_red"}, {["x"] = 7, ["meta"] = {["fields"] = {}, ["inventory"] = {}}, ["y"] = 7, ["param1"] = 93, ["z"] = 10, ["name"] = "cottages:roof_red"}, {["x"] = 7, ["meta"] = {["fields"] = {}, ["inventory"] = {}}, ["y"] = 7, ["z"] = 11, ["name"] = "fachwerk:clay"}, {["x"] = 7, ["meta"] = {["fields"] = {}, ["inventory"] = {}}, ["y"] = 7, ["z"] = 12, ["name"] = "default:wood"}, {["x"] = 7, ["meta"] = {["fields"] = {}, ["inventory"] = {}}, ["y"] = 7, ["z"] = 13, ["name"] = "default:wood"}, {["x"] = 7, ["meta"] = {["fields"] = {}, ["inventory"] = {}}, ["y"] = 7, ["z"] = 14, ["name"] = "default:wood"}, {["x"] = 7, ["meta"] = {["fields"] = {}, ["inventory"] = {}}, ["y"] = 7, ["z"] = 15, ["name"] = "default:wood"}, {["x"] = 7, ["meta"] = {["fields"] = {}, ["inventory"] = {}}, ["y"] = 7, ["z"] = 16, ["name"] = "default:wood"}, {["x"] = 7, ["meta"] = {["fields"] = {}, ["inventory"] = {}}, ["y"] = 7, ["z"] = 17, ["name"] = "default:wood"}, {["x"] = 7, ["meta"] = {["fields"] = {}, ["inventory"] = {}}, ["y"] = 7, ["z"] = 18, ["name"] = "default:wood"}, {["x"] = 7, ["meta"] = {["fields"] = {}, ["inventory"] = {}}, ["y"] = 7, ["z"] = 19, ["name"] = "default:wood"}, {["x"] = 7, ["meta"] = {["fields"] = {}, ["inventory"] = {}}, ["y"] = 7, ["z"] = 20, ["name"] = "fachwerk:clay"}, {["x"] = 7, ["meta"] = {["fields"] = {}, ["inventory"] = {}}, ["param2"] = 2, ["y"] = 7, ["param1"] = 189, ["z"] = 21, ["name"] = "cottages:roof_red"}, {["x"] = 7, ["meta"] = {["fields"] = {}, ["inventory"] = {}}, ["y"] = 8, ["param1"] = 93, ["z"] = 11, ["name"] = "cottages:roof_connector_red"}, {["x"] = 7, ["meta"] = {["fields"] = {}, ["inventory"] = {}}, ["y"] = 8, ["z"] = 12, ["name"] = "default:wood"}, {["x"] = 7, ["meta"] = {["fields"] = {}, ["inventory"] = {}}, ["y"] = 8, ["z"] = 13, ["name"] = "default:wood"}, {["x"] = 7, ["meta"] = {["fields"] = {}, ["inventory"] = {}}, ["y"] = 8, ["z"] = 14, ["name"] = "default:wood"}, {["x"] = 7, ["meta"] = {["fields"] = {}, ["inventory"] = {}}, ["y"] = 8, ["z"] = 15, ["name"] = "default:wood"}, {["x"] = 7, ["meta"] = {["fields"] = {}, ["inventory"] = {}}, ["y"] = 8, ["z"] = 16, ["name"] = "default:wood"}, {["x"] = 7, ["meta"] = {["fields"] = {}, ["inventory"] = {}}, ["y"] = 8, ["z"] = 17, ["name"] = "default:wood"}, {["x"] = 7, ["meta"] = {["fields"] = {}, ["inventory"] = {}}, ["y"] = 8, ["z"] = 18, ["name"] = "default:wood"}, {["x"] = 7, ["meta"] = {["fields"] = {}, ["inventory"] = {}}, ["y"] = 8, ["z"] = 19, ["name"] = "default:wood"}, {["x"] = 7, ["meta"] = {["fields"] = {}, ["inventory"] = {}}, ["param2"] = 2, ["y"] = 8, ["param1"] = 157, ["z"] = 20, ["name"] = "cottages:roof_connector_red"}, {["x"] = 7, ["meta"] = {["fields"] = {}, ["inventory"] = {}}, ["y"] = 9, ["param1"] = 93, ["z"] = 12, ["name"] = "cottages:roof_connector_red"}, {["x"] = 7, ["meta"] = {["fields"] = {}, ["inventory"] = {}}, ["y"] = 9, ["z"] = 13, ["name"] = "default:wood"}, {["x"] = 7, ["meta"] = {["fields"] = {}, ["inventory"] = {}}, ["y"] = 9, ["z"] = 14, ["name"] = "default:wood"}, {["x"] = 7, ["meta"] = {["fields"] = {}, ["inventory"] = {}}, ["y"] = 9, ["z"] = 15, ["name"] = "default:wood"}, {["x"] = 7, ["meta"] = {["fields"] = {}, ["inventory"] = {}}, ["y"] = 9, ["z"] = 16, ["name"] = "default:wood"}, {["x"] = 7, ["meta"] = {["fields"] = {}, ["inventory"] = {}}, ["y"] = 9, ["z"] = 17, ["name"] = "default:wood"}, {["x"] = 7, ["meta"] = {["fields"] = {}, ["inventory"] = {}}, ["y"] = 9, ["z"] = 18, ["name"] = "default:wood"}, {["x"] = 7, ["meta"] = {["fields"] = {}, ["inventory"] = {}}, ["param2"] = 2, ["y"] = 9, ["param1"] = 141, ["z"] = 19, ["name"] = "cottages:roof_connector_red"}, {["x"] = 7, ["meta"] = {["fields"] = {}, ["inventory"] = {}}, ["y"] = 10, ["param1"] = 93, ["z"] = 13, ["name"] = "cottages:roof_connector_red"}, {["x"] = 7, ["meta"] = {["fields"] = {}, ["inventory"] = {}}, ["y"] = 10, ["z"] = 14, ["name"] = "default:wood"}, {["x"] = 7, ["meta"] = {["fields"] = {}, ["inventory"] = {}}, ["y"] = 10, ["z"] = 15, ["name"] = "default:wood"}, {["x"] = 7, ["meta"] = {["fields"] = {}, ["inventory"] = {}}, ["y"] = 10, ["z"] = 16, ["name"] = "default:wood"}, {["x"] = 7, ["meta"] = {["fields"] = {}, ["inventory"] = {}}, ["y"] = 10, ["z"] = 17, ["name"] = "default:wood"}, {["x"] = 7, ["meta"] = {["fields"] = {}, ["inventory"] = {}}, ["param2"] = 2, ["y"] = 10, ["param1"] = 141, ["z"] = 18, ["name"] = "cottages:roof_connector_red"}, {["x"] = 7, ["meta"] = {["fields"] = {}, ["inventory"] = {}}, ["y"] = 11, ["param1"] = 93, ["z"] = 14, ["name"] = "cottages:roof_connector_red"}, {["x"] = 7, ["meta"] = {["fields"] = {}, ["inventory"] = {}}, ["y"] = 11, ["z"] = 15, ["name"] = "default:wood"}, {["x"] = 7, ["meta"] = {["fields"] = {}, ["inventory"] = {}}, ["y"] = 11, ["z"] = 16, ["name"] = "default:wood"}, {["x"] = 7, ["meta"] = {["fields"] = {}, ["inventory"] = {}}, ["param2"] = 2, ["y"] = 11, ["param1"] = 141, ["z"] = 17, ["name"] = "cottages:roof_connector_red"}, {["x"] = 7, ["meta"] = {["fields"] = {}, ["inventory"] = {}}, ["y"] = 12, ["param1"] = 93, ["z"] = 15, ["name"] = "cottages:roof_connector_red"}, {["x"] = 7, ["meta"] = {["fields"] = {}, ["inventory"] = {}}, ["param2"] = 2, ["y"] = 12, ["param1"] = 109, ["z"] = 16, ["name"] = "cottages:roof_connector_red"}}